[2024-12-27 22:48:05 +0530] [8297] [INFO] Starting gunicorn 23.0.0
[2024-12-27 22:48:05 +0530] [8297] [INFO] Listening at: http://0.0.0.0:8000 (8297)
[2024-12-27 22:48:05 +0530] [8297] [INFO] Using worker: sync
[2024-12-27 22:48:05 +0530] [8301] [INFO] Booting worker with pid: 8301
[2024-12-27 22:48:05 +0530] [8302] [INFO] Booting worker with pid: 8302
[2024-12-27 22:48:05 +0530] [8303] [INFO] Booting worker with pid: 8303
[2024-12-27 22:48:05 +0530] [8305] [INFO] Booting worker with pid: 8305
[2024-12-27 22:48:05 +0530] [8307] [INFO] Booting worker with pid: 8307
[2024-12-27 22:48:05 +0530] [8309] [INFO] Booting worker with pid: 8309
[2024-12-27 22:48:05 +0530] [8311] [INFO] Booting worker with pid: 8311
[2024-12-27 22:48:05 +0530] [8313] [INFO] Booting worker with pid: 8313
[2024-12-27 22:48:05 +0530] [8314] [INFO] Booting worker with pid: 8314
[2024-12-27 22:48:05 +0530] [8315] [INFO] Booting worker with pid: 8315
[2024-12-27 23:16:56 +0530] [8309] [INFO] Worker exiting (pid: 8309)
[2024-12-27 23:16:56 +0530] [8302] [INFO] Worker exiting (pid: 8302)
[2024-12-27 23:16:56 +0530] [8311] [INFO] Worker exiting (pid: 8311)
[2024-12-27 23:16:56 +0530] [8315] [INFO] Worker exiting (pid: 8315)
[2024-12-27 23:16:56 +0530] [8314] [INFO] Worker exiting (pid: 8314)
[2024-12-27 23:16:56 +0530] [8307] [INFO] Worker exiting (pid: 8307)
[2024-12-27 23:16:56 +0530] [8301] [INFO] Worker exiting (pid: 8301)
[2024-12-27 23:16:56 +0530] [8303] [INFO] Worker exiting (pid: 8303)
[2024-12-27 23:16:56 +0530] [8305] [INFO] Worker exiting (pid: 8305)
[2024-12-27 23:16:56 +0530] [8313] [INFO] Worker exiting (pid: 8313)
[2024-12-27 23:16:56 +0530] [8297] [INFO] Handling signal: term
[2024-12-27 23:16:56 +0530] [8297] [ERROR] Worker (pid:8301) was sent SIGTERM!
[2024-12-27 23:16:56 +0530] [8297] [ERROR] Worker (pid:8309) was sent SIGTERM!
[2024-12-27 23:16:56 +0530] [8297] [ERROR] Worker (pid:8302) was sent SIGTERM!
[2024-12-27 23:16:56 +0530] [8297] [ERROR] Worker (pid:8314) was sent SIGTERM!
[2024-12-27 23:16:56 +0530] [8297] [ERROR] Worker (pid:8313) was sent SIGTERM!
[2024-12-27 23:16:56 +0530] [8297] [ERROR] Worker (pid:8305) was sent SIGTERM!
[2024-12-27 23:16:56 +0530] [8297] [ERROR] Worker (pid:8303) was sent SIGTERM!
[2024-12-27 23:16:56 +0530] [8297] [ERROR] Worker (pid:8315) was sent SIGTERM!
[2024-12-27 23:16:56 +0530] [8297] [INFO] Shutting down: Master
[2024-12-27 23:16:59 +0530] [11560] [INFO] Starting gunicorn 23.0.0
[2024-12-27 23:16:59 +0530] [11560] [INFO] Listening at: http://0.0.0.0:8000 (11560)
[2024-12-27 23:16:59 +0530] [11560] [INFO] Using worker: sync
[2024-12-27 23:16:59 +0530] [11564] [INFO] Booting worker with pid: 11564
[2024-12-27 23:16:59 +0530] [11565] [INFO] Booting worker with pid: 11565
[2024-12-27 23:16:59 +0530] [11566] [INFO] Booting worker with pid: 11566
[2024-12-27 23:16:59 +0530] [11567] [INFO] Booting worker with pid: 11567
[2024-12-27 23:16:59 +0530] [11570] [INFO] Booting worker with pid: 11570
[2024-12-27 23:16:59 +0530] [11571] [INFO] Booting worker with pid: 11571
[2024-12-27 23:16:59 +0530] [11574] [INFO] Booting worker with pid: 11574
[2024-12-27 23:16:59 +0530] [11576] [INFO] Booting worker with pid: 11576
[2024-12-27 23:16:59 +0530] [11578] [INFO] Booting worker with pid: 11578
[2024-12-27 23:16:59 +0530] [11579] [INFO] Booting worker with pid: 11579
[2024-12-28 02:14:07 +0530] [11564] [INFO] Worker reloading: /home/malhar/User_Drive/Projects/cn_ddos_protection_python/webserver/main.py modified
[2024-12-28 02:14:07 +0530] [11578] [INFO] Worker reloading: /home/malhar/User_Drive/Projects/cn_ddos_protection_python/webserver/main.py modified
[2024-12-28 02:14:07 +0530] [11564] [INFO] Worker exiting (pid: 11564)
[2024-12-28 02:14:07 +0530] [11578] [INFO] Worker exiting (pid: 11578)
[2024-12-28 02:14:07 +0530] [11576] [INFO] Worker reloading: /home/malhar/User_Drive/Projects/cn_ddos_protection_python/webserver/main.py modified
[2024-12-28 02:14:07 +0530] [11571] [INFO] Worker reloading: /home/malhar/User_Drive/Projects/cn_ddos_protection_python/webserver/main.py modified
[2024-12-28 02:14:07 +0530] [11576] [INFO] Worker exiting (pid: 11576)
[2024-12-28 02:14:07 +0530] [11571] [INFO] Worker exiting (pid: 11571)
[2024-12-28 02:14:07 +0530] [24612] [INFO] Booting worker with pid: 24612
[2024-12-28 02:14:07 +0530] [11565] [INFO] Worker reloading: /home/malhar/User_Drive/Projects/cn_ddos_protection_python/webserver/main.py modified
[2024-12-28 02:14:07 +0530] [11565] [INFO] Worker exiting (pid: 11565)
[2024-12-28 02:14:07 +0530] [11570] [INFO] Worker reloading: /home/malhar/User_Drive/Projects/cn_ddos_protection_python/webserver/main.py modified
[2024-12-28 02:14:07 +0530] [11570] [INFO] Worker exiting (pid: 11570)
[2024-12-28 02:14:07 +0530] [24613] [INFO] Booting worker with pid: 24613
[2024-12-28 02:14:07 +0530] [24614] [INFO] Booting worker with pid: 24614
[2024-12-28 02:14:07 +0530] [24616] [INFO] Booting worker with pid: 24616
[2024-12-28 02:14:07 +0530] [24619] [INFO] Booting worker with pid: 24619
[2024-12-28 02:14:07 +0530] [24622] [INFO] Booting worker with pid: 24622
[2024-12-28 02:14:07 +0530] [11579] [INFO] Worker reloading: /home/malhar/User_Drive/Projects/cn_ddos_protection_python/webserver/main.py modified
[2024-12-28 02:14:07 +0530] [11579] [INFO] Worker exiting (pid: 11579)
[2024-12-28 02:14:07 +0530] [11574] [INFO] Worker reloading: /home/malhar/User_Drive/Projects/cn_ddos_protection_python/webserver/main.py modified
[2024-12-28 02:14:07 +0530] [11574] [INFO] Worker exiting (pid: 11574)
[2024-12-28 02:14:07 +0530] [24624] [INFO] Booting worker with pid: 24624
[2024-12-28 02:14:07 +0530] [24626] [INFO] Booting worker with pid: 24626
[2024-12-28 02:14:08 +0530] [11566] [INFO] Worker reloading: /home/malhar/User_Drive/Projects/cn_ddos_protection_python/webserver/main.py modified
[2024-12-28 02:14:08 +0530] [11567] [INFO] Worker reloading: /home/malhar/User_Drive/Projects/cn_ddos_protection_python/webserver/main.py modified
[2024-12-28 02:14:08 +0530] [11566] [INFO] Worker exiting (pid: 11566)
[2024-12-28 02:14:08 +0530] [11567] [INFO] Worker exiting (pid: 11567)
[2024-12-28 02:14:08 +0530] [24629] [INFO] Booting worker with pid: 24629
[2024-12-28 02:14:08 +0530] [24630] [INFO] Booting worker with pid: 24630
[2024-12-28 02:16:47 +0530] [24624] [INFO] Worker reloading: /home/malhar/User_Drive/Projects/cn_ddos_protection_python/webserver/main.py modified
[2024-12-28 02:16:47 +0530] [24624] [INFO] Worker exiting (pid: 24624)
[2024-12-28 02:16:47 +0530] [24940] [INFO] Booting worker with pid: 24940
[2024-12-28 02:16:47 +0530] [24626] [INFO] Worker reloading: /home/malhar/User_Drive/Projects/cn_ddos_protection_python/webserver/main.py modified
[2024-12-28 02:16:47 +0530] [24626] [INFO] Worker exiting (pid: 24626)
[2024-12-28 02:16:47 +0530] [24941] [INFO] Booting worker with pid: 24941
[2024-12-28 02:16:47 +0530] [24629] [INFO] Worker reloading: /home/malhar/User_Drive/Projects/cn_ddos_protection_python/webserver/main.py modified
[2024-12-28 02:16:47 +0530] [24629] [INFO] Worker exiting (pid: 24629)
[2024-12-28 02:16:47 +0530] [24630] [INFO] Worker reloading: /home/malhar/User_Drive/Projects/cn_ddos_protection_python/webserver/main.py modified
[2024-12-28 02:16:47 +0530] [24630] [INFO] Worker exiting (pid: 24630)
[2024-12-28 02:16:47 +0530] [24612] [INFO] Worker reloading: /home/malhar/User_Drive/Projects/cn_ddos_protection_python/webserver/main.py modified
[2024-12-28 02:16:47 +0530] [24612] [INFO] Worker exiting (pid: 24612)
[2024-12-28 02:16:47 +0530] [24950] [INFO] Booting worker with pid: 24950
[2024-12-28 02:16:47 +0530] [24951] [INFO] Booting worker with pid: 24951
[2024-12-28 02:16:47 +0530] [24613] [INFO] Worker reloading: /home/malhar/User_Drive/Projects/cn_ddos_protection_python/webserver/main.py modified
[2024-12-28 02:16:47 +0530] [24613] [INFO] Worker exiting (pid: 24613)
[2024-12-28 02:16:47 +0530] [24614] [INFO] Worker reloading: /home/malhar/User_Drive/Projects/cn_ddos_protection_python/webserver/main.py modified
[2024-12-28 02:16:47 +0530] [24614] [INFO] Worker exiting (pid: 24614)
[2024-12-28 02:16:47 +0530] [24952] [INFO] Booting worker with pid: 24952
[2024-12-28 02:16:47 +0530] [24955] [INFO] Booting worker with pid: 24955
[2024-12-28 02:16:47 +0530] [24616] [INFO] Worker reloading: /home/malhar/User_Drive/Projects/cn_ddos_protection_python/webserver/main.py modified
[2024-12-28 02:16:47 +0530] [24616] [INFO] Worker exiting (pid: 24616)
[2024-12-28 02:16:47 +0530] [24956] [INFO] Booting worker with pid: 24956
[2024-12-28 02:16:47 +0530] [24619] [INFO] Worker reloading: /home/malhar/User_Drive/Projects/cn_ddos_protection_python/webserver/main.py modified
[2024-12-28 02:16:47 +0530] [24619] [INFO] Worker exiting (pid: 24619)
[2024-12-28 02:16:47 +0530] [24959] [INFO] Booting worker with pid: 24959
[2024-12-28 02:16:47 +0530] [24622] [INFO] Worker reloading: /home/malhar/User_Drive/Projects/cn_ddos_protection_python/webserver/main.py modified
[2024-12-28 02:16:47 +0530] [24622] [INFO] Worker exiting (pid: 24622)
[2024-12-28 02:16:47 +0530] [24961] [INFO] Booting worker with pid: 24961
[2024-12-28 02:16:48 +0530] [24963] [INFO] Booting worker with pid: 24963
[2024-12-28 02:16:52 +0530] [24955] [INFO] Worker reloading: /home/malhar/User_Drive/Projects/cn_ddos_protection_python/webserver/main.py modified
[2024-12-28 02:16:52 +0530] [24955] [INFO] Worker exiting (pid: 24955)
[2024-12-28 02:16:52 +0530] [24956] [INFO] Worker reloading: /home/malhar/User_Drive/Projects/cn_ddos_protection_python/webserver/main.py modified
[2024-12-28 02:16:52 +0530] [24956] [INFO] Worker exiting (pid: 24956)
[2024-12-28 02:16:52 +0530] [24979] [INFO] Booting worker with pid: 24979
[2024-12-28 02:16:52 +0530] [24979] [ERROR] Expected one or more names after 'import' (main.py, line 2)
Traceback (most recent call last):
  File "/home/malhar/User_Drive/Projects/cn_ddos_protection_python/webserver/webs_venv/lib/python3.13/site-packages/gunicorn/workers/base.py", line 147, in load_wsgi
    self.wsgi = self.app.wsgi()
                ~~~~~~~~~~~~~^^
  File "/home/malhar/User_Drive/Projects/cn_ddos_protection_python/webserver/webs_venv/lib/python3.13/site-packages/gunicorn/app/base.py", line 66, in wsgi
    self.callable = self.load()
                    ~~~~~~~~~^^
  File "/home/malhar/User_Drive/Projects/cn_ddos_protection_python/webserver/webs_venv/lib/python3.13/site-packages/gunicorn/app/wsgiapp.py", line 57, in load
    return self.load_wsgiapp()
           ~~~~~~~~~~~~~~~~~^^
  File "/home/malhar/User_Drive/Projects/cn_ddos_protection_python/webserver/webs_venv/lib/python3.13/site-packages/gunicorn/app/wsgiapp.py", line 47, in load_wsgiapp
    return util.import_app(self.app_uri)
           ~~~~~~~~~~~~~~~^^^^^^^^^^^^^^
  File "/home/malhar/User_Drive/Projects/cn_ddos_protection_python/webserver/webs_venv/lib/python3.13/site-packages/gunicorn/util.py", line 370, in import_app
    mod = importlib.import_module(module)
  File "/usr/lib/python3.13/importlib/__init__.py", line 88, in import_module
    return _bootstrap._gcd_import(name[level:], package, level)
           ~~~~~~~~~~~~~~~~~~~~~~^^^^^^^^^^^^^^^^^^^^^^^^^^^^^^
  File "<frozen importlib._bootstrap>", line 1387, in _gcd_import
  File "<frozen importlib._bootstrap>", line 1360, in _find_and_load
  File "<frozen importlib._bootstrap>", line 1331, in _find_and_load_unlocked
  File "<frozen importlib._bootstrap>", line 935, in _load_unlocked
  File "<frozen importlib._bootstrap_external>", line 1022, in exec_module
  File "<frozen importlib._bootstrap_external>", line 1160, in get_code
  File "<frozen importlib._bootstrap_external>", line 1090, in source_to_code
  File "<frozen importlib._bootstrap>", line 488, in _call_with_frames_removed
  File "/home/malhar/User_Drive/Projects/cn_ddos_protection_python/webserver/main.py", line 2
    import 
           ^
SyntaxError: Expected one or more names after 'import'
[2024-12-28 02:16:52 +0530] [24981] [INFO] Booting worker with pid: 24981
[2024-12-28 02:16:52 +0530] [24981] [ERROR] Expected one or more names after 'import' (main.py, line 2)
Traceback (most recent call last):
  File "/home/malhar/User_Drive/Projects/cn_ddos_protection_python/webserver/webs_venv/lib/python3.13/site-packages/gunicorn/workers/base.py", line 147, in load_wsgi
    self.wsgi = self.app.wsgi()
                ~~~~~~~~~~~~~^^
  File "/home/malhar/User_Drive/Projects/cn_ddos_protection_python/webserver/webs_venv/lib/python3.13/site-packages/gunicorn/app/base.py", line 66, in wsgi
    self.callable = self.load()
                    ~~~~~~~~~^^
  File "/home/malhar/User_Drive/Projects/cn_ddos_protection_python/webserver/webs_venv/lib/python3.13/site-packages/gunicorn/app/wsgiapp.py", line 57, in load
    return self.load_wsgiapp()
           ~~~~~~~~~~~~~~~~~^^
  File "/home/malhar/User_Drive/Projects/cn_ddos_protection_python/webserver/webs_venv/lib/python3.13/site-packages/gunicorn/app/wsgiapp.py", line 47, in load_wsgiapp
    return util.import_app(self.app_uri)
           ~~~~~~~~~~~~~~~^^^^^^^^^^^^^^
  File "/home/malhar/User_Drive/Projects/cn_ddos_protection_python/webserver/webs_venv/lib/python3.13/site-packages/gunicorn/util.py", line 370, in import_app
    mod = importlib.import_module(module)
  File "/usr/lib/python3.13/importlib/__init__.py", line 88, in import_module
    return _bootstrap._gcd_import(name[level:], package, level)
           ~~~~~~~~~~~~~~~~~~~~~~^^^^^^^^^^^^^^^^^^^^^^^^^^^^^^
  File "<frozen importlib._bootstrap>", line 1387, in _gcd_import
  File "<frozen importlib._bootstrap>", line 1360, in _find_and_load
  File "<frozen importlib._bootstrap>", line 1331, in _find_and_load_unlocked
  File "<frozen importlib._bootstrap>", line 935, in _load_unlocked
  File "<frozen importlib._bootstrap_external>", line 1022, in exec_module
  File "<frozen importlib._bootstrap_external>", line 1160, in get_code
  File "<frozen importlib._bootstrap_external>", line 1090, in source_to_code
  File "<frozen importlib._bootstrap>", line 488, in _call_with_frames_removed
  File "/home/malhar/User_Drive/Projects/cn_ddos_protection_python/webserver/main.py", line 2
    import 
           ^
SyntaxError: Expected one or more names after 'import'
[2024-12-28 02:16:53 +0530] [24959] [INFO] Worker reloading: /home/malhar/User_Drive/Projects/cn_ddos_protection_python/webserver/main.py modified
[2024-12-28 02:16:53 +0530] [24959] [INFO] Worker exiting (pid: 24959)
[2024-12-28 02:16:53 +0530] [24961] [INFO] Worker reloading: /home/malhar/User_Drive/Projects/cn_ddos_protection_python/webserver/main.py modified
[2024-12-28 02:16:53 +0530] [24961] [INFO] Worker exiting (pid: 24961)
[2024-12-28 02:16:53 +0530] [24988] [INFO] Booting worker with pid: 24988
[2024-12-28 02:16:53 +0530] [24988] [ERROR] Expected one or more names after 'import' (main.py, line 2)
Traceback (most recent call last):
  File "/home/malhar/User_Drive/Projects/cn_ddos_protection_python/webserver/webs_venv/lib/python3.13/site-packages/gunicorn/workers/base.py", line 147, in load_wsgi
    self.wsgi = self.app.wsgi()
                ~~~~~~~~~~~~~^^
  File "/home/malhar/User_Drive/Projects/cn_ddos_protection_python/webserver/webs_venv/lib/python3.13/site-packages/gunicorn/app/base.py", line 66, in wsgi
    self.callable = self.load()
                    ~~~~~~~~~^^
  File "/home/malhar/User_Drive/Projects/cn_ddos_protection_python/webserver/webs_venv/lib/python3.13/site-packages/gunicorn/app/wsgiapp.py", line 57, in load
    return self.load_wsgiapp()
           ~~~~~~~~~~~~~~~~~^^
  File "/home/malhar/User_Drive/Projects/cn_ddos_protection_python/webserver/webs_venv/lib/python3.13/site-packages/gunicorn/app/wsgiapp.py", line 47, in load_wsgiapp
    return util.import_app(self.app_uri)
           ~~~~~~~~~~~~~~~^^^^^^^^^^^^^^
  File "/home/malhar/User_Drive/Projects/cn_ddos_protection_python/webserver/webs_venv/lib/python3.13/site-packages/gunicorn/util.py", line 370, in import_app
    mod = importlib.import_module(module)
  File "/usr/lib/python3.13/importlib/__init__.py", line 88, in import_module
    return _bootstrap._gcd_import(name[level:], package, level)
           ~~~~~~~~~~~~~~~~~~~~~~^^^^^^^^^^^^^^^^^^^^^^^^^^^^^^
  File "<frozen importlib._bootstrap>", line 1387, in _gcd_import
  File "<frozen importlib._bootstrap>", line 1360, in _find_and_load
  File "<frozen importlib._bootstrap>", line 1331, in _find_and_load_unlocked
  File "<frozen importlib._bootstrap>", line 935, in _load_unlocked
  File "<frozen importlib._bootstrap_external>", line 1022, in exec_module
  File "<frozen importlib._bootstrap_external>", line 1160, in get_code
  File "<frozen importlib._bootstrap_external>", line 1090, in source_to_code
  File "<frozen importlib._bootstrap>", line 488, in _call_with_frames_removed
  File "/home/malhar/User_Drive/Projects/cn_ddos_protection_python/webserver/main.py", line 2
    import 
           ^
SyntaxError: Expected one or more names after 'import'
[2024-12-28 02:16:53 +0530] [24990] [INFO] Booting worker with pid: 24990
[2024-12-28 02:16:53 +0530] [24963] [INFO] Worker reloading: /home/malhar/User_Drive/Projects/cn_ddos_protection_python/webserver/main.py modified
[2024-12-28 02:16:53 +0530] [24963] [INFO] Worker exiting (pid: 24963)
[2024-12-28 02:16:53 +0530] [24990] [ERROR] Expected one or more names after 'import' (main.py, line 2)
Traceback (most recent call last):
  File "/home/malhar/User_Drive/Projects/cn_ddos_protection_python/webserver/webs_venv/lib/python3.13/site-packages/gunicorn/workers/base.py", line 147, in load_wsgi
    self.wsgi = self.app.wsgi()
                ~~~~~~~~~~~~~^^
  File "/home/malhar/User_Drive/Projects/cn_ddos_protection_python/webserver/webs_venv/lib/python3.13/site-packages/gunicorn/app/base.py", line 66, in wsgi
    self.callable = self.load()
                    ~~~~~~~~~^^
  File "/home/malhar/User_Drive/Projects/cn_ddos_protection_python/webserver/webs_venv/lib/python3.13/site-packages/gunicorn/app/wsgiapp.py", line 57, in load
    return self.load_wsgiapp()
           ~~~~~~~~~~~~~~~~~^^
  File "/home/malhar/User_Drive/Projects/cn_ddos_protection_python/webserver/webs_venv/lib/python3.13/site-packages/gunicorn/app/wsgiapp.py", line 47, in load_wsgiapp
    return util.import_app(self.app_uri)
           ~~~~~~~~~~~~~~~^^^^^^^^^^^^^^
  File "/home/malhar/User_Drive/Projects/cn_ddos_protection_python/webserver/webs_venv/lib/python3.13/site-packages/gunicorn/util.py", line 370, in import_app
    mod = importlib.import_module(module)
  File "/usr/lib/python3.13/importlib/__init__.py", line 88, in import_module
    return _bootstrap._gcd_import(name[level:], package, level)
           ~~~~~~~~~~~~~~~~~~~~~~^^^^^^^^^^^^^^^^^^^^^^^^^^^^^^
  File "<frozen importlib._bootstrap>", line 1387, in _gcd_import
  File "<frozen importlib._bootstrap>", line 1360, in _find_and_load
  File "<frozen importlib._bootstrap>", line 1331, in _find_and_load_unlocked
  File "<frozen importlib._bootstrap>", line 935, in _load_unlocked
  File "<frozen importlib._bootstrap_external>", line 1022, in exec_module
  File "<frozen importlib._bootstrap_external>", line 1160, in get_code
  File "<frozen importlib._bootstrap_external>", line 1090, in source_to_code
  File "<frozen importlib._bootstrap>", line 488, in _call_with_frames_removed
  File "/home/malhar/User_Drive/Projects/cn_ddos_protection_python/webserver/main.py", line 2
    import 
           ^
SyntaxError: Expected one or more names after 'import'
[2024-12-28 02:16:53 +0530] [24940] [INFO] Worker reloading: /home/malhar/User_Drive/Projects/cn_ddos_protection_python/webserver/main.py modified
[2024-12-28 02:16:53 +0530] [24940] [INFO] Worker exiting (pid: 24940)
[2024-12-28 02:16:53 +0530] [24992] [INFO] Booting worker with pid: 24992
[2024-12-28 02:16:53 +0530] [24992] [ERROR] Expected one or more names after 'import' (main.py, line 2)
Traceback (most recent call last):
  File "/home/malhar/User_Drive/Projects/cn_ddos_protection_python/webserver/webs_venv/lib/python3.13/site-packages/gunicorn/workers/base.py", line 147, in load_wsgi
    self.wsgi = self.app.wsgi()
                ~~~~~~~~~~~~~^^
  File "/home/malhar/User_Drive/Projects/cn_ddos_protection_python/webserver/webs_venv/lib/python3.13/site-packages/gunicorn/app/base.py", line 66, in wsgi
    self.callable = self.load()
                    ~~~~~~~~~^^
  File "/home/malhar/User_Drive/Projects/cn_ddos_protection_python/webserver/webs_venv/lib/python3.13/site-packages/gunicorn/app/wsgiapp.py", line 57, in load
    return self.load_wsgiapp()
           ~~~~~~~~~~~~~~~~~^^
  File "/home/malhar/User_Drive/Projects/cn_ddos_protection_python/webserver/webs_venv/lib/python3.13/site-packages/gunicorn/app/wsgiapp.py", line 47, in load_wsgiapp
    return util.import_app(self.app_uri)
           ~~~~~~~~~~~~~~~^^^^^^^^^^^^^^
  File "/home/malhar/User_Drive/Projects/cn_ddos_protection_python/webserver/webs_venv/lib/python3.13/site-packages/gunicorn/util.py", line 370, in import_app
    mod = importlib.import_module(module)
  File "/usr/lib/python3.13/importlib/__init__.py", line 88, in import_module
    return _bootstrap._gcd_import(name[level:], package, level)
           ~~~~~~~~~~~~~~~~~~~~~~^^^^^^^^^^^^^^^^^^^^^^^^^^^^^^
  File "<frozen importlib._bootstrap>", line 1387, in _gcd_import
  File "<frozen importlib._bootstrap>", line 1360, in _find_and_load
  File "<frozen importlib._bootstrap>", line 1331, in _find_and_load_unlocked
  File "<frozen importlib._bootstrap>", line 935, in _load_unlocked
  File "<frozen importlib._bootstrap_external>", line 1022, in exec_module
  File "<frozen importlib._bootstrap_external>", line 1160, in get_code
  File "<frozen importlib._bootstrap_external>", line 1090, in source_to_code
  File "<frozen importlib._bootstrap>", line 488, in _call_with_frames_removed
  File "/home/malhar/User_Drive/Projects/cn_ddos_protection_python/webserver/main.py", line 2
    import 
           ^
SyntaxError: Expected one or more names after 'import'
[2024-12-28 02:16:53 +0530] [24941] [INFO] Worker reloading: /home/malhar/User_Drive/Projects/cn_ddos_protection_python/webserver/main.py modified
[2024-12-28 02:16:53 +0530] [24941] [INFO] Worker exiting (pid: 24941)
[2024-12-28 02:16:53 +0530] [24994] [INFO] Booting worker with pid: 24994
[2024-12-28 02:16:53 +0530] [24994] [ERROR] Expected one or more names after 'import' (main.py, line 2)
Traceback (most recent call last):
  File "/home/malhar/User_Drive/Projects/cn_ddos_protection_python/webserver/webs_venv/lib/python3.13/site-packages/gunicorn/workers/base.py", line 147, in load_wsgi
    self.wsgi = self.app.wsgi()
                ~~~~~~~~~~~~~^^
  File "/home/malhar/User_Drive/Projects/cn_ddos_protection_python/webserver/webs_venv/lib/python3.13/site-packages/gunicorn/app/base.py", line 66, in wsgi
    self.callable = self.load()
                    ~~~~~~~~~^^
  File "/home/malhar/User_Drive/Projects/cn_ddos_protection_python/webserver/webs_venv/lib/python3.13/site-packages/gunicorn/app/wsgiapp.py", line 57, in load
    return self.load_wsgiapp()
           ~~~~~~~~~~~~~~~~~^^
  File "/home/malhar/User_Drive/Projects/cn_ddos_protection_python/webserver/webs_venv/lib/python3.13/site-packages/gunicorn/app/wsgiapp.py", line 47, in load_wsgiapp
    return util.import_app(self.app_uri)
           ~~~~~~~~~~~~~~~^^^^^^^^^^^^^^
  File "/home/malhar/User_Drive/Projects/cn_ddos_protection_python/webserver/webs_venv/lib/python3.13/site-packages/gunicorn/util.py", line 370, in import_app
    mod = importlib.import_module(module)
  File "/usr/lib/python3.13/importlib/__init__.py", line 88, in import_module
    return _bootstrap._gcd_import(name[level:], package, level)
           ~~~~~~~~~~~~~~~~~~~~~~^^^^^^^^^^^^^^^^^^^^^^^^^^^^^^
  File "<frozen importlib._bootstrap>", line 1387, in _gcd_import
  File "<frozen importlib._bootstrap>", line 1360, in _find_and_load
  File "<frozen importlib._bootstrap>", line 1331, in _find_and_load_unlocked
  File "<frozen importlib._bootstrap>", line 935, in _load_unlocked
  File "<frozen importlib._bootstrap_external>", line 1022, in exec_module
  File "<frozen importlib._bootstrap_external>", line 1160, in get_code
  File "<frozen importlib._bootstrap_external>", line 1090, in source_to_code
  File "<frozen importlib._bootstrap>", line 488, in _call_with_frames_removed
  File "/home/malhar/User_Drive/Projects/cn_ddos_protection_python/webserver/main.py", line 2
    import 
           ^
SyntaxError: Expected one or more names after 'import'
[2024-12-28 02:16:53 +0530] [24996] [INFO] Booting worker with pid: 24996
[2024-12-28 02:16:53 +0530] [24996] [ERROR] Expected one or more names after 'import' (main.py, line 2)
Traceback (most recent call last):
  File "/home/malhar/User_Drive/Projects/cn_ddos_protection_python/webserver/webs_venv/lib/python3.13/site-packages/gunicorn/workers/base.py", line 147, in load_wsgi
    self.wsgi = self.app.wsgi()
                ~~~~~~~~~~~~~^^
  File "/home/malhar/User_Drive/Projects/cn_ddos_protection_python/webserver/webs_venv/lib/python3.13/site-packages/gunicorn/app/base.py", line 66, in wsgi
    self.callable = self.load()
                    ~~~~~~~~~^^
  File "/home/malhar/User_Drive/Projects/cn_ddos_protection_python/webserver/webs_venv/lib/python3.13/site-packages/gunicorn/app/wsgiapp.py", line 57, in load
    return self.load_wsgiapp()
           ~~~~~~~~~~~~~~~~~^^
  File "/home/malhar/User_Drive/Projects/cn_ddos_protection_python/webserver/webs_venv/lib/python3.13/site-packages/gunicorn/app/wsgiapp.py", line 47, in load_wsgiapp
    return util.import_app(self.app_uri)
           ~~~~~~~~~~~~~~~^^^^^^^^^^^^^^
  File "/home/malhar/User_Drive/Projects/cn_ddos_protection_python/webserver/webs_venv/lib/python3.13/site-packages/gunicorn/util.py", line 370, in import_app
    mod = importlib.import_module(module)
  File "/usr/lib/python3.13/importlib/__init__.py", line 88, in import_module
    return _bootstrap._gcd_import(name[level:], package, level)
           ~~~~~~~~~~~~~~~~~~~~~~^^^^^^^^^^^^^^^^^^^^^^^^^^^^^^
  File "<frozen importlib._bootstrap>", line 1387, in _gcd_import
  File "<frozen importlib._bootstrap>", line 1360, in _find_and_load
  File "<frozen importlib._bootstrap>", line 1331, in _find_and_load_unlocked
  File "<frozen importlib._bootstrap>", line 935, in _load_unlocked
  File "<frozen importlib._bootstrap_external>", line 1022, in exec_module
  File "<frozen importlib._bootstrap_external>", line 1160, in get_code
  File "<frozen importlib._bootstrap_external>", line 1090, in source_to_code
  File "<frozen importlib._bootstrap>", line 488, in _call_with_frames_removed
  File "/home/malhar/User_Drive/Projects/cn_ddos_protection_python/webserver/main.py", line 2
    import 
           ^
SyntaxError: Expected one or more names after 'import'
[2024-12-28 02:16:53 +0530] [24950] [INFO] Worker reloading: /home/malhar/User_Drive/Projects/cn_ddos_protection_python/webserver/main.py modified
[2024-12-28 02:16:53 +0530] [24950] [INFO] Worker exiting (pid: 24950)
[2024-12-28 02:16:53 +0530] [24951] [INFO] Worker reloading: /home/malhar/User_Drive/Projects/cn_ddos_protection_python/webserver/main.py modified
[2024-12-28 02:16:53 +0530] [24951] [INFO] Worker exiting (pid: 24951)
[2024-12-28 02:16:53 +0530] [24999] [INFO] Booting worker with pid: 24999
[2024-12-28 02:16:53 +0530] [24999] [ERROR] Expected one or more names after 'import' (main.py, line 2)
Traceback (most recent call last):
  File "/home/malhar/User_Drive/Projects/cn_ddos_protection_python/webserver/webs_venv/lib/python3.13/site-packages/gunicorn/workers/base.py", line 147, in load_wsgi
    self.wsgi = self.app.wsgi()
                ~~~~~~~~~~~~~^^
  File "/home/malhar/User_Drive/Projects/cn_ddos_protection_python/webserver/webs_venv/lib/python3.13/site-packages/gunicorn/app/base.py", line 66, in wsgi
    self.callable = self.load()
                    ~~~~~~~~~^^
  File "/home/malhar/User_Drive/Projects/cn_ddos_protection_python/webserver/webs_venv/lib/python3.13/site-packages/gunicorn/app/wsgiapp.py", line 57, in load
    return self.load_wsgiapp()
           ~~~~~~~~~~~~~~~~~^^
  File "/home/malhar/User_Drive/Projects/cn_ddos_protection_python/webserver/webs_venv/lib/python3.13/site-packages/gunicorn/app/wsgiapp.py", line 47, in load_wsgiapp
    return util.import_app(self.app_uri)
           ~~~~~~~~~~~~~~~^^^^^^^^^^^^^^
  File "/home/malhar/User_Drive/Projects/cn_ddos_protection_python/webserver/webs_venv/lib/python3.13/site-packages/gunicorn/util.py", line 370, in import_app
    mod = importlib.import_module(module)
  File "/usr/lib/python3.13/importlib/__init__.py", line 88, in import_module
    return _bootstrap._gcd_import(name[level:], package, level)
           ~~~~~~~~~~~~~~~~~~~~~~^^^^^^^^^^^^^^^^^^^^^^^^^^^^^^
  File "<frozen importlib._bootstrap>", line 1387, in _gcd_import
  File "<frozen importlib._bootstrap>", line 1360, in _find_and_load
  File "<frozen importlib._bootstrap>", line 1331, in _find_and_load_unlocked
  File "<frozen importlib._bootstrap>", line 935, in _load_unlocked
  File "<frozen importlib._bootstrap_external>", line 1022, in exec_module
  File "<frozen importlib._bootstrap_external>", line 1160, in get_code
  File "<frozen importlib._bootstrap_external>", line 1090, in source_to_code
  File "<frozen importlib._bootstrap>", line 488, in _call_with_frames_removed
  File "/home/malhar/User_Drive/Projects/cn_ddos_protection_python/webserver/main.py", line 2
    import 
           ^
SyntaxError: Expected one or more names after 'import'
[2024-12-28 02:16:53 +0530] [24952] [INFO] Worker reloading: /home/malhar/User_Drive/Projects/cn_ddos_protection_python/webserver/main.py modified
[2024-12-28 02:16:53 +0530] [24952] [INFO] Worker exiting (pid: 24952)
[2024-12-28 02:16:53 +0530] [25001] [INFO] Booting worker with pid: 25001
[2024-12-28 02:16:53 +0530] [25001] [ERROR] Expected one or more names after 'import' (main.py, line 2)
Traceback (most recent call last):
  File "/home/malhar/User_Drive/Projects/cn_ddos_protection_python/webserver/webs_venv/lib/python3.13/site-packages/gunicorn/workers/base.py", line 147, in load_wsgi
    self.wsgi = self.app.wsgi()
                ~~~~~~~~~~~~~^^
  File "/home/malhar/User_Drive/Projects/cn_ddos_protection_python/webserver/webs_venv/lib/python3.13/site-packages/gunicorn/app/base.py", line 66, in wsgi
    self.callable = self.load()
                    ~~~~~~~~~^^
  File "/home/malhar/User_Drive/Projects/cn_ddos_protection_python/webserver/webs_venv/lib/python3.13/site-packages/gunicorn/app/wsgiapp.py", line 57, in load
    return self.load_wsgiapp()
           ~~~~~~~~~~~~~~~~~^^
  File "/home/malhar/User_Drive/Projects/cn_ddos_protection_python/webserver/webs_venv/lib/python3.13/site-packages/gunicorn/app/wsgiapp.py", line 47, in load_wsgiapp
    return util.import_app(self.app_uri)
           ~~~~~~~~~~~~~~~^^^^^^^^^^^^^^
  File "/home/malhar/User_Drive/Projects/cn_ddos_protection_python/webserver/webs_venv/lib/python3.13/site-packages/gunicorn/util.py", line 370, in import_app
    mod = importlib.import_module(module)
  File "/usr/lib/python3.13/importlib/__init__.py", line 88, in import_module
    return _bootstrap._gcd_import(name[level:], package, level)
           ~~~~~~~~~~~~~~~~~~~~~~^^^^^^^^^^^^^^^^^^^^^^^^^^^^^^
  File "<frozen importlib._bootstrap>", line 1387, in _gcd_import
  File "<frozen importlib._bootstrap>", line 1360, in _find_and_load
  File "<frozen importlib._bootstrap>", line 1331, in _find_and_load_unlocked
  File "<frozen importlib._bootstrap>", line 935, in _load_unlocked
  File "<frozen importlib._bootstrap_external>", line 1022, in exec_module
  File "<frozen importlib._bootstrap_external>", line 1160, in get_code
  File "<frozen importlib._bootstrap_external>", line 1090, in source_to_code
  File "<frozen importlib._bootstrap>", line 488, in _call_with_frames_removed
  File "/home/malhar/User_Drive/Projects/cn_ddos_protection_python/webserver/main.py", line 2
    import 
           ^
SyntaxError: Expected one or more names after 'import'
[2024-12-28 02:16:53 +0530] [25003] [INFO] Booting worker with pid: 25003
[2024-12-28 02:16:53 +0530] [25003] [ERROR] Expected one or more names after 'import' (main.py, line 2)
Traceback (most recent call last):
  File "/home/malhar/User_Drive/Projects/cn_ddos_protection_python/webserver/webs_venv/lib/python3.13/site-packages/gunicorn/workers/base.py", line 147, in load_wsgi
    self.wsgi = self.app.wsgi()
                ~~~~~~~~~~~~~^^
  File "/home/malhar/User_Drive/Projects/cn_ddos_protection_python/webserver/webs_venv/lib/python3.13/site-packages/gunicorn/app/base.py", line 66, in wsgi
    self.callable = self.load()
                    ~~~~~~~~~^^
  File "/home/malhar/User_Drive/Projects/cn_ddos_protection_python/webserver/webs_venv/lib/python3.13/site-packages/gunicorn/app/wsgiapp.py", line 57, in load
    return self.load_wsgiapp()
           ~~~~~~~~~~~~~~~~~^^
  File "/home/malhar/User_Drive/Projects/cn_ddos_protection_python/webserver/webs_venv/lib/python3.13/site-packages/gunicorn/app/wsgiapp.py", line 47, in load_wsgiapp
    return util.import_app(self.app_uri)
           ~~~~~~~~~~~~~~~^^^^^^^^^^^^^^
  File "/home/malhar/User_Drive/Projects/cn_ddos_protection_python/webserver/webs_venv/lib/python3.13/site-packages/gunicorn/util.py", line 370, in import_app
    mod = importlib.import_module(module)
  File "/usr/lib/python3.13/importlib/__init__.py", line 88, in import_module
    return _bootstrap._gcd_import(name[level:], package, level)
           ~~~~~~~~~~~~~~~~~~~~~~^^^^^^^^^^^^^^^^^^^^^^^^^^^^^^
  File "<frozen importlib._bootstrap>", line 1387, in _gcd_import
  File "<frozen importlib._bootstrap>", line 1360, in _find_and_load
  File "<frozen importlib._bootstrap>", line 1331, in _find_and_load_unlocked
  File "<frozen importlib._bootstrap>", line 935, in _load_unlocked
  File "<frozen importlib._bootstrap_external>", line 1022, in exec_module
  File "<frozen importlib._bootstrap_external>", line 1160, in get_code
  File "<frozen importlib._bootstrap_external>", line 1090, in source_to_code
  File "<frozen importlib._bootstrap>", line 488, in _call_with_frames_removed
  File "/home/malhar/User_Drive/Projects/cn_ddos_protection_python/webserver/main.py", line 2
    import 
           ^
SyntaxError: Expected one or more names after 'import'
[2024-12-28 02:16:56 +0530] [24979] [INFO] Worker reloading: /home/malhar/User_Drive/Projects/cn_ddos_protection_python/webserver/main.py modified
[2024-12-28 02:16:56 +0530] [24979] [INFO] Worker exiting (pid: 24979)
[2024-12-28 02:16:56 +0530] [25014] [INFO] Booting worker with pid: 25014
[2024-12-28 02:16:57 +0530] [25003] [INFO] Worker reloading: /home/malhar/User_Drive/Projects/cn_ddos_protection_python/webserver/main.py modified
[2024-12-28 02:16:57 +0530] [25003] [INFO] Worker exiting (pid: 25003)
[2024-12-28 02:16:57 +0530] [24981] [INFO] Worker reloading: /home/malhar/User_Drive/Projects/cn_ddos_protection_python/webserver/main.py modified
[2024-12-28 02:16:57 +0530] [24981] [INFO] Worker exiting (pid: 24981)
[2024-12-28 02:16:57 +0530] [25015] [INFO] Booting worker with pid: 25015
[2024-12-28 02:16:57 +0530] [24988] [INFO] Worker reloading: /home/malhar/User_Drive/Projects/cn_ddos_protection_python/webserver/main.py modified
[2024-12-28 02:16:57 +0530] [24988] [INFO] Worker exiting (pid: 24988)
[2024-12-28 02:16:57 +0530] [25016] [INFO] Booting worker with pid: 25016
[2024-12-28 02:16:57 +0530] [24990] [INFO] Worker reloading: /home/malhar/User_Drive/Projects/cn_ddos_protection_python/webserver/main.py modified
[2024-12-28 02:16:57 +0530] [24990] [INFO] Worker exiting (pid: 24990)
[2024-12-28 02:16:57 +0530] [25018] [INFO] Booting worker with pid: 25018
[2024-12-28 02:16:57 +0530] [24992] [INFO] Worker reloading: /home/malhar/User_Drive/Projects/cn_ddos_protection_python/webserver/main.py modified
[2024-12-28 02:16:57 +0530] [24992] [INFO] Worker exiting (pid: 24992)
[2024-12-28 02:16:57 +0530] [24994] [INFO] Worker reloading: /home/malhar/User_Drive/Projects/cn_ddos_protection_python/webserver/main.py modified
[2024-12-28 02:16:57 +0530] [24994] [INFO] Worker exiting (pid: 24994)
[2024-12-28 02:16:57 +0530] [25020] [INFO] Booting worker with pid: 25020
[2024-12-28 02:16:57 +0530] [25023] [INFO] Booting worker with pid: 25023
[2024-12-28 02:16:57 +0530] [24996] [INFO] Worker reloading: /home/malhar/User_Drive/Projects/cn_ddos_protection_python/webserver/main.py modified
[2024-12-28 02:16:57 +0530] [24996] [INFO] Worker exiting (pid: 24996)
[2024-12-28 02:16:57 +0530] [25024] [INFO] Booting worker with pid: 25024
[2024-12-28 02:16:57 +0530] [25026] [INFO] Booting worker with pid: 25026
[2024-12-28 02:16:57 +0530] [24999] [INFO] Worker reloading: /home/malhar/User_Drive/Projects/cn_ddos_protection_python/webserver/main.py modified
[2024-12-28 02:16:57 +0530] [24999] [INFO] Worker exiting (pid: 24999)
[2024-12-28 02:16:57 +0530] [25036] [INFO] Booting worker with pid: 25036
[2024-12-28 02:16:57 +0530] [25001] [INFO] Worker reloading: /home/malhar/User_Drive/Projects/cn_ddos_protection_python/webserver/main.py modified
[2024-12-28 02:16:57 +0530] [25001] [INFO] Worker exiting (pid: 25001)
[2024-12-28 02:16:57 +0530] [25037] [INFO] Booting worker with pid: 25037
[2024-12-28 02:17:00 +0530] [25036] [INFO] Worker reloading: /home/malhar/User_Drive/Projects/cn_ddos_protection_python/webserver/main.py modified
[2024-12-28 02:17:00 +0530] [25036] [INFO] Worker exiting (pid: 25036)
[2024-12-28 02:17:01 +0530] [25045] [INFO] Booting worker with pid: 25045
[2024-12-28 02:17:01 +0530] [25045] [ERROR] invalid syntax (main.py, line 3)
Traceback (most recent call last):
  File "/home/malhar/User_Drive/Projects/cn_ddos_protection_python/webserver/webs_venv/lib/python3.13/site-packages/gunicorn/workers/base.py", line 147, in load_wsgi
    self.wsgi = self.app.wsgi()
                ~~~~~~~~~~~~~^^
  File "/home/malhar/User_Drive/Projects/cn_ddos_protection_python/webserver/webs_venv/lib/python3.13/site-packages/gunicorn/app/base.py", line 66, in wsgi
    self.callable = self.load()
                    ~~~~~~~~~^^
  File "/home/malhar/User_Drive/Projects/cn_ddos_protection_python/webserver/webs_venv/lib/python3.13/site-packages/gunicorn/app/wsgiapp.py", line 57, in load
    return self.load_wsgiapp()
           ~~~~~~~~~~~~~~~~~^^
  File "/home/malhar/User_Drive/Projects/cn_ddos_protection_python/webserver/webs_venv/lib/python3.13/site-packages/gunicorn/app/wsgiapp.py", line 47, in load_wsgiapp
    return util.import_app(self.app_uri)
           ~~~~~~~~~~~~~~~^^^^^^^^^^^^^^
  File "/home/malhar/User_Drive/Projects/cn_ddos_protection_python/webserver/webs_venv/lib/python3.13/site-packages/gunicorn/util.py", line 370, in import_app
    mod = importlib.import_module(module)
  File "/usr/lib/python3.13/importlib/__init__.py", line 88, in import_module
    return _bootstrap._gcd_import(name[level:], package, level)
           ~~~~~~~~~~~~~~~~~~~~~~^^^^^^^^^^^^^^^^^^^^^^^^^^^^^^
  File "<frozen importlib._bootstrap>", line 1387, in _gcd_import
  File "<frozen importlib._bootstrap>", line 1360, in _find_and_load
  File "<frozen importlib._bootstrap>", line 1331, in _find_and_load_unlocked
  File "<frozen importlib._bootstrap>", line 935, in _load_unlocked
  File "<frozen importlib._bootstrap_external>", line 1022, in exec_module
  File "<frozen importlib._bootstrap_external>", line 1160, in get_code
  File "<frozen importlib._bootstrap_external>", line 1090, in source_to_code
  File "<frozen importlib._bootstrap>", line 488, in _call_with_frames_removed
  File "/home/malhar/User_Drive/Projects/cn_ddos_protection_python/webserver/main.py", line 3
    from mysql
              ^
SyntaxError: invalid syntax
[2024-12-28 02:17:01 +0530] [25037] [INFO] Worker reloading: /home/malhar/User_Drive/Projects/cn_ddos_protection_python/webserver/main.py modified
[2024-12-28 02:17:01 +0530] [25037] [INFO] Worker exiting (pid: 25037)
[2024-12-28 02:17:01 +0530] [25047] [INFO] Booting worker with pid: 25047
[2024-12-28 02:17:01 +0530] [25014] [INFO] Worker reloading: /home/malhar/User_Drive/Projects/cn_ddos_protection_python/webserver/main.py modified
[2024-12-28 02:17:01 +0530] [25014] [INFO] Worker exiting (pid: 25014)
[2024-12-28 02:17:01 +0530] [25047] [ERROR] invalid syntax (main.py, line 3)
Traceback (most recent call last):
  File "/home/malhar/User_Drive/Projects/cn_ddos_protection_python/webserver/webs_venv/lib/python3.13/site-packages/gunicorn/workers/base.py", line 147, in load_wsgi
    self.wsgi = self.app.wsgi()
                ~~~~~~~~~~~~~^^
  File "/home/malhar/User_Drive/Projects/cn_ddos_protection_python/webserver/webs_venv/lib/python3.13/site-packages/gunicorn/app/base.py", line 66, in wsgi
    self.callable = self.load()
                    ~~~~~~~~~^^
  File "/home/malhar/User_Drive/Projects/cn_ddos_protection_python/webserver/webs_venv/lib/python3.13/site-packages/gunicorn/app/wsgiapp.py", line 57, in load
    return self.load_wsgiapp()
           ~~~~~~~~~~~~~~~~~^^
  File "/home/malhar/User_Drive/Projects/cn_ddos_protection_python/webserver/webs_venv/lib/python3.13/site-packages/gunicorn/app/wsgiapp.py", line 47, in load_wsgiapp
    return util.import_app(self.app_uri)
           ~~~~~~~~~~~~~~~^^^^^^^^^^^^^^
  File "/home/malhar/User_Drive/Projects/cn_ddos_protection_python/webserver/webs_venv/lib/python3.13/site-packages/gunicorn/util.py", line 370, in import_app
    mod = importlib.import_module(module)
  File "/usr/lib/python3.13/importlib/__init__.py", line 88, in import_module
    return _bootstrap._gcd_import(name[level:], package, level)
           ~~~~~~~~~~~~~~~~~~~~~~^^^^^^^^^^^^^^^^^^^^^^^^^^^^^^
  File "<frozen importlib._bootstrap>", line 1387, in _gcd_import
  File "<frozen importlib._bootstrap>", line 1360, in _find_and_load
  File "<frozen importlib._bootstrap>", line 1331, in _find_and_load_unlocked
  File "<frozen importlib._bootstrap>", line 935, in _load_unlocked
  File "<frozen importlib._bootstrap_external>", line 1022, in exec_module
  File "<frozen importlib._bootstrap_external>", line 1160, in get_code
  File "<frozen importlib._bootstrap_external>", line 1090, in source_to_code
  File "<frozen importlib._bootstrap>", line 488, in _call_with_frames_removed
  File "/home/malhar/User_Drive/Projects/cn_ddos_protection_python/webserver/main.py", line 3
    from mysql
              ^
SyntaxError: invalid syntax
[2024-12-28 02:17:01 +0530] [25015] [INFO] Worker reloading: /home/malhar/User_Drive/Projects/cn_ddos_protection_python/webserver/main.py modified
[2024-12-28 02:17:01 +0530] [25015] [INFO] Worker exiting (pid: 25015)
[2024-12-28 02:17:01 +0530] [25049] [INFO] Booting worker with pid: 25049
[2024-12-28 02:17:01 +0530] [25049] [ERROR] invalid syntax (main.py, line 3)
Traceback (most recent call last):
  File "/home/malhar/User_Drive/Projects/cn_ddos_protection_python/webserver/webs_venv/lib/python3.13/site-packages/gunicorn/workers/base.py", line 147, in load_wsgi
    self.wsgi = self.app.wsgi()
                ~~~~~~~~~~~~~^^
  File "/home/malhar/User_Drive/Projects/cn_ddos_protection_python/webserver/webs_venv/lib/python3.13/site-packages/gunicorn/app/base.py", line 66, in wsgi
    self.callable = self.load()
                    ~~~~~~~~~^^
  File "/home/malhar/User_Drive/Projects/cn_ddos_protection_python/webserver/webs_venv/lib/python3.13/site-packages/gunicorn/app/wsgiapp.py", line 57, in load
    return self.load_wsgiapp()
           ~~~~~~~~~~~~~~~~~^^
  File "/home/malhar/User_Drive/Projects/cn_ddos_protection_python/webserver/webs_venv/lib/python3.13/site-packages/gunicorn/app/wsgiapp.py", line 47, in load_wsgiapp
    return util.import_app(self.app_uri)
           ~~~~~~~~~~~~~~~^^^^^^^^^^^^^^
  File "/home/malhar/User_Drive/Projects/cn_ddos_protection_python/webserver/webs_venv/lib/python3.13/site-packages/gunicorn/util.py", line 370, in import_app
    mod = importlib.import_module(module)
  File "/usr/lib/python3.13/importlib/__init__.py", line 88, in import_module
    return _bootstrap._gcd_import(name[level:], package, level)
           ~~~~~~~~~~~~~~~~~~~~~~^^^^^^^^^^^^^^^^^^^^^^^^^^^^^^
  File "<frozen importlib._bootstrap>", line 1387, in _gcd_import
  File "<frozen importlib._bootstrap>", line 1360, in _find_and_load
  File "<frozen importlib._bootstrap>", line 1331, in _find_and_load_unlocked
  File "<frozen importlib._bootstrap>", line 935, in _load_unlocked
  File "<frozen importlib._bootstrap_external>", line 1022, in exec_module
  File "<frozen importlib._bootstrap_external>", line 1160, in get_code
  File "<frozen importlib._bootstrap_external>", line 1090, in source_to_code
  File "<frozen importlib._bootstrap>", line 488, in _call_with_frames_removed
  File "/home/malhar/User_Drive/Projects/cn_ddos_protection_python/webserver/main.py", line 3
    from mysql
              ^
SyntaxError: invalid syntax
[2024-12-28 02:17:01 +0530] [25051] [INFO] Booting worker with pid: 25051
[2024-12-28 02:17:01 +0530] [25016] [INFO] Worker reloading: /home/malhar/User_Drive/Projects/cn_ddos_protection_python/webserver/main.py modified
[2024-12-28 02:17:01 +0530] [25051] [ERROR] invalid syntax (main.py, line 3)
Traceback (most recent call last):
  File "/home/malhar/User_Drive/Projects/cn_ddos_protection_python/webserver/webs_venv/lib/python3.13/site-packages/gunicorn/workers/base.py", line 147, in load_wsgi
    self.wsgi = self.app.wsgi()
                ~~~~~~~~~~~~~^^
  File "/home/malhar/User_Drive/Projects/cn_ddos_protection_python/webserver/webs_venv/lib/python3.13/site-packages/gunicorn/app/base.py", line 66, in wsgi
    self.callable = self.load()
                    ~~~~~~~~~^^
  File "/home/malhar/User_Drive/Projects/cn_ddos_protection_python/webserver/webs_venv/lib/python3.13/site-packages/gunicorn/app/wsgiapp.py", line 57, in load
    return self.load_wsgiapp()
           ~~~~~~~~~~~~~~~~~^^
  File "/home/malhar/User_Drive/Projects/cn_ddos_protection_python/webserver/webs_venv/lib/python3.13/site-packages/gunicorn/app/wsgiapp.py", line 47, in load_wsgiapp
    return util.import_app(self.app_uri)
           ~~~~~~~~~~~~~~~^^^^^^^^^^^^^^
  File "/home/malhar/User_Drive/Projects/cn_ddos_protection_python/webserver/webs_venv/lib/python3.13/site-packages/gunicorn/util.py", line 370, in import_app
    mod = importlib.import_module(module)
  File "/usr/lib/python3.13/importlib/__init__.py", line 88, in import_module
    return _bootstrap._gcd_import(name[level:], package, level)
           ~~~~~~~~~~~~~~~~~~~~~~^^^^^^^^^^^^^^^^^^^^^^^^^^^^^^
  File "<frozen importlib._bootstrap>", line 1387, in _gcd_import
  File "<frozen importlib._bootstrap>", line 1360, in _find_and_load
  File "<frozen importlib._bootstrap>", line 1331, in _find_and_load_unlocked
  File "<frozen importlib._bootstrap>", line 935, in _load_unlocked
  File "<frozen importlib._bootstrap_external>", line 1022, in exec_module
  File "<frozen importlib._bootstrap_external>", line 1160, in get_code
  File "<frozen importlib._bootstrap_external>", line 1090, in source_to_code
  File "<frozen importlib._bootstrap>", line 488, in _call_with_frames_removed
  File "/home/malhar/User_Drive/Projects/cn_ddos_protection_python/webserver/main.py", line 3
    from mysql
              ^
SyntaxError: invalid syntax
[2024-12-28 02:17:01 +0530] [25016] [INFO] Worker exiting (pid: 25016)
[2024-12-28 02:17:01 +0530] [25018] [INFO] Worker reloading: /home/malhar/User_Drive/Projects/cn_ddos_protection_python/webserver/main.py modified
[2024-12-28 02:17:01 +0530] [25018] [INFO] Worker exiting (pid: 25018)
[2024-12-28 02:17:01 +0530] [25053] [INFO] Booting worker with pid: 25053
[2024-12-28 02:17:01 +0530] [25053] [ERROR] invalid syntax (main.py, line 3)
Traceback (most recent call last):
  File "/home/malhar/User_Drive/Projects/cn_ddos_protection_python/webserver/webs_venv/lib/python3.13/site-packages/gunicorn/workers/base.py", line 147, in load_wsgi
    self.wsgi = self.app.wsgi()
                ~~~~~~~~~~~~~^^
  File "/home/malhar/User_Drive/Projects/cn_ddos_protection_python/webserver/webs_venv/lib/python3.13/site-packages/gunicorn/app/base.py", line 66, in wsgi
    self.callable = self.load()
                    ~~~~~~~~~^^
  File "/home/malhar/User_Drive/Projects/cn_ddos_protection_python/webserver/webs_venv/lib/python3.13/site-packages/gunicorn/app/wsgiapp.py", line 57, in load
    return self.load_wsgiapp()
           ~~~~~~~~~~~~~~~~~^^
  File "/home/malhar/User_Drive/Projects/cn_ddos_protection_python/webserver/webs_venv/lib/python3.13/site-packages/gunicorn/app/wsgiapp.py", line 47, in load_wsgiapp
    return util.import_app(self.app_uri)
           ~~~~~~~~~~~~~~~^^^^^^^^^^^^^^
  File "/home/malhar/User_Drive/Projects/cn_ddos_protection_python/webserver/webs_venv/lib/python3.13/site-packages/gunicorn/util.py", line 370, in import_app
    mod = importlib.import_module(module)
  File "/usr/lib/python3.13/importlib/__init__.py", line 88, in import_module
    return _bootstrap._gcd_import(name[level:], package, level)
           ~~~~~~~~~~~~~~~~~~~~~~^^^^^^^^^^^^^^^^^^^^^^^^^^^^^^
  File "<frozen importlib._bootstrap>", line 1387, in _gcd_import
  File "<frozen importlib._bootstrap>", line 1360, in _find_and_load
  File "<frozen importlib._bootstrap>", line 1331, in _find_and_load_unlocked
  File "<frozen importlib._bootstrap>", line 935, in _load_unlocked
  File "<frozen importlib._bootstrap_external>", line 1022, in exec_module
  File "<frozen importlib._bootstrap_external>", line 1160, in get_code
  File "<frozen importlib._bootstrap_external>", line 1090, in source_to_code
  File "<frozen importlib._bootstrap>", line 488, in _call_with_frames_removed
  File "/home/malhar/User_Drive/Projects/cn_ddos_protection_python/webserver/main.py", line 3
    from mysql
              ^
SyntaxError: invalid syntax
[2024-12-28 02:17:01 +0530] [25020] [INFO] Worker reloading: /home/malhar/User_Drive/Projects/cn_ddos_protection_python/webserver/main.py modified
[2024-12-28 02:17:01 +0530] [25020] [INFO] Worker exiting (pid: 25020)
[2024-12-28 02:17:01 +0530] [25055] [INFO] Booting worker with pid: 25055
[2024-12-28 02:17:01 +0530] [25055] [ERROR] invalid syntax (main.py, line 3)
Traceback (most recent call last):
  File "/home/malhar/User_Drive/Projects/cn_ddos_protection_python/webserver/webs_venv/lib/python3.13/site-packages/gunicorn/workers/base.py", line 147, in load_wsgi
    self.wsgi = self.app.wsgi()
                ~~~~~~~~~~~~~^^
  File "/home/malhar/User_Drive/Projects/cn_ddos_protection_python/webserver/webs_venv/lib/python3.13/site-packages/gunicorn/app/base.py", line 66, in wsgi
    self.callable = self.load()
                    ~~~~~~~~~^^
  File "/home/malhar/User_Drive/Projects/cn_ddos_protection_python/webserver/webs_venv/lib/python3.13/site-packages/gunicorn/app/wsgiapp.py", line 57, in load
    return self.load_wsgiapp()
           ~~~~~~~~~~~~~~~~~^^
  File "/home/malhar/User_Drive/Projects/cn_ddos_protection_python/webserver/webs_venv/lib/python3.13/site-packages/gunicorn/app/wsgiapp.py", line 47, in load_wsgiapp
    return util.import_app(self.app_uri)
           ~~~~~~~~~~~~~~~^^^^^^^^^^^^^^
  File "/home/malhar/User_Drive/Projects/cn_ddos_protection_python/webserver/webs_venv/lib/python3.13/site-packages/gunicorn/util.py", line 370, in import_app
    mod = importlib.import_module(module)
  File "/usr/lib/python3.13/importlib/__init__.py", line 88, in import_module
    return _bootstrap._gcd_import(name[level:], package, level)
           ~~~~~~~~~~~~~~~~~~~~~~^^^^^^^^^^^^^^^^^^^^^^^^^^^^^^
  File "<frozen importlib._bootstrap>", line 1387, in _gcd_import
  File "<frozen importlib._bootstrap>", line 1360, in _find_and_load
  File "<frozen importlib._bootstrap>", line 1331, in _find_and_load_unlocked
  File "<frozen importlib._bootstrap>", line 935, in _load_unlocked
  File "<frozen importlib._bootstrap_external>", line 1022, in exec_module
  File "<frozen importlib._bootstrap_external>", line 1160, in get_code
  File "<frozen importlib._bootstrap_external>", line 1090, in source_to_code
  File "<frozen importlib._bootstrap>", line 488, in _call_with_frames_removed
  File "/home/malhar/User_Drive/Projects/cn_ddos_protection_python/webserver/main.py", line 3
    from mysql
              ^
SyntaxError: invalid syntax
[2024-12-28 02:17:01 +0530] [25057] [INFO] Booting worker with pid: 25057
[2024-12-28 02:17:01 +0530] [25057] [ERROR] invalid syntax (main.py, line 3)
Traceback (most recent call last):
  File "/home/malhar/User_Drive/Projects/cn_ddos_protection_python/webserver/webs_venv/lib/python3.13/site-packages/gunicorn/workers/base.py", line 147, in load_wsgi
    self.wsgi = self.app.wsgi()
                ~~~~~~~~~~~~~^^
  File "/home/malhar/User_Drive/Projects/cn_ddos_protection_python/webserver/webs_venv/lib/python3.13/site-packages/gunicorn/app/base.py", line 66, in wsgi
    self.callable = self.load()
                    ~~~~~~~~~^^
  File "/home/malhar/User_Drive/Projects/cn_ddos_protection_python/webserver/webs_venv/lib/python3.13/site-packages/gunicorn/app/wsgiapp.py", line 57, in load
    return self.load_wsgiapp()
           ~~~~~~~~~~~~~~~~~^^
  File "/home/malhar/User_Drive/Projects/cn_ddos_protection_python/webserver/webs_venv/lib/python3.13/site-packages/gunicorn/app/wsgiapp.py", line 47, in load_wsgiapp
    return util.import_app(self.app_uri)
           ~~~~~~~~~~~~~~~^^^^^^^^^^^^^^
  File "/home/malhar/User_Drive/Projects/cn_ddos_protection_python/webserver/webs_venv/lib/python3.13/site-packages/gunicorn/util.py", line 370, in import_app
    mod = importlib.import_module(module)
  File "/usr/lib/python3.13/importlib/__init__.py", line 88, in import_module
    return _bootstrap._gcd_import(name[level:], package, level)
           ~~~~~~~~~~~~~~~~~~~~~~^^^^^^^^^^^^^^^^^^^^^^^^^^^^^^
  File "<frozen importlib._bootstrap>", line 1387, in _gcd_import
  File "<frozen importlib._bootstrap>", line 1360, in _find_and_load
  File "<frozen importlib._bootstrap>", line 1331, in _find_and_load_unlocked
  File "<frozen importlib._bootstrap>", line 935, in _load_unlocked
  File "<frozen importlib._bootstrap_external>", line 1022, in exec_module
  File "<frozen importlib._bootstrap_external>", line 1160, in get_code
  File "<frozen importlib._bootstrap_external>", line 1090, in source_to_code
  File "<frozen importlib._bootstrap>", line 488, in _call_with_frames_removed
  File "/home/malhar/User_Drive/Projects/cn_ddos_protection_python/webserver/main.py", line 3
    from mysql
              ^
SyntaxError: invalid syntax
[2024-12-28 02:17:01 +0530] [25023] [INFO] Worker reloading: /home/malhar/User_Drive/Projects/cn_ddos_protection_python/webserver/main.py modified
[2024-12-28 02:17:01 +0530] [25023] [INFO] Worker exiting (pid: 25023)
[2024-12-28 02:17:01 +0530] [25024] [INFO] Worker reloading: /home/malhar/User_Drive/Projects/cn_ddos_protection_python/webserver/main.py modified
[2024-12-28 02:17:01 +0530] [25024] [INFO] Worker exiting (pid: 25024)
[2024-12-28 02:17:01 +0530] [25026] [INFO] Worker reloading: /home/malhar/User_Drive/Projects/cn_ddos_protection_python/webserver/main.py modified
[2024-12-28 02:17:01 +0530] [25026] [INFO] Worker exiting (pid: 25026)
[2024-12-28 02:17:01 +0530] [25059] [INFO] Booting worker with pid: 25059
[2024-12-28 02:17:01 +0530] [25059] [ERROR] invalid syntax (main.py, line 3)
Traceback (most recent call last):
  File "/home/malhar/User_Drive/Projects/cn_ddos_protection_python/webserver/webs_venv/lib/python3.13/site-packages/gunicorn/workers/base.py", line 147, in load_wsgi
    self.wsgi = self.app.wsgi()
                ~~~~~~~~~~~~~^^
  File "/home/malhar/User_Drive/Projects/cn_ddos_protection_python/webserver/webs_venv/lib/python3.13/site-packages/gunicorn/app/base.py", line 66, in wsgi
    self.callable = self.load()
                    ~~~~~~~~~^^
  File "/home/malhar/User_Drive/Projects/cn_ddos_protection_python/webserver/webs_venv/lib/python3.13/site-packages/gunicorn/app/wsgiapp.py", line 57, in load
    return self.load_wsgiapp()
           ~~~~~~~~~~~~~~~~~^^
  File "/home/malhar/User_Drive/Projects/cn_ddos_protection_python/webserver/webs_venv/lib/python3.13/site-packages/gunicorn/app/wsgiapp.py", line 47, in load_wsgiapp
    return util.import_app(self.app_uri)
           ~~~~~~~~~~~~~~~^^^^^^^^^^^^^^
  File "/home/malhar/User_Drive/Projects/cn_ddos_protection_python/webserver/webs_venv/lib/python3.13/site-packages/gunicorn/util.py", line 370, in import_app
    mod = importlib.import_module(module)
  File "/usr/lib/python3.13/importlib/__init__.py", line 88, in import_module
    return _bootstrap._gcd_import(name[level:], package, level)
           ~~~~~~~~~~~~~~~~~~~~~~^^^^^^^^^^^^^^^^^^^^^^^^^^^^^^
  File "<frozen importlib._bootstrap>", line 1387, in _gcd_import
  File "<frozen importlib._bootstrap>", line 1360, in _find_and_load
  File "<frozen importlib._bootstrap>", line 1331, in _find_and_load_unlocked
  File "<frozen importlib._bootstrap>", line 935, in _load_unlocked
  File "<frozen importlib._bootstrap_external>", line 1022, in exec_module
  File "<frozen importlib._bootstrap_external>", line 1160, in get_code
  File "<frozen importlib._bootstrap_external>", line 1090, in source_to_code
  File "<frozen importlib._bootstrap>", line 488, in _call_with_frames_removed
  File "/home/malhar/User_Drive/Projects/cn_ddos_protection_python/webserver/main.py", line 3
    from mysql
              ^
SyntaxError: invalid syntax
[2024-12-28 02:17:01 +0530] [25061] [INFO] Booting worker with pid: 25061
[2024-12-28 02:17:01 +0530] [25061] [ERROR] invalid syntax (main.py, line 3)
Traceback (most recent call last):
  File "/home/malhar/User_Drive/Projects/cn_ddos_protection_python/webserver/webs_venv/lib/python3.13/site-packages/gunicorn/workers/base.py", line 147, in load_wsgi
    self.wsgi = self.app.wsgi()
                ~~~~~~~~~~~~~^^
  File "/home/malhar/User_Drive/Projects/cn_ddos_protection_python/webserver/webs_venv/lib/python3.13/site-packages/gunicorn/app/base.py", line 66, in wsgi
    self.callable = self.load()
                    ~~~~~~~~~^^
  File "/home/malhar/User_Drive/Projects/cn_ddos_protection_python/webserver/webs_venv/lib/python3.13/site-packages/gunicorn/app/wsgiapp.py", line 57, in load
    return self.load_wsgiapp()
           ~~~~~~~~~~~~~~~~~^^
  File "/home/malhar/User_Drive/Projects/cn_ddos_protection_python/webserver/webs_venv/lib/python3.13/site-packages/gunicorn/app/wsgiapp.py", line 47, in load_wsgiapp
    return util.import_app(self.app_uri)
           ~~~~~~~~~~~~~~~^^^^^^^^^^^^^^
  File "/home/malhar/User_Drive/Projects/cn_ddos_protection_python/webserver/webs_venv/lib/python3.13/site-packages/gunicorn/util.py", line 370, in import_app
    mod = importlib.import_module(module)
  File "/usr/lib/python3.13/importlib/__init__.py", line 88, in import_module
    return _bootstrap._gcd_import(name[level:], package, level)
           ~~~~~~~~~~~~~~~~~~~~~~^^^^^^^^^^^^^^^^^^^^^^^^^^^^^^
  File "<frozen importlib._bootstrap>", line 1387, in _gcd_import
  File "<frozen importlib._bootstrap>", line 1360, in _find_and_load
  File "<frozen importlib._bootstrap>", line 1331, in _find_and_load_unlocked
  File "<frozen importlib._bootstrap>", line 935, in _load_unlocked
  File "<frozen importlib._bootstrap_external>", line 1022, in exec_module
  File "<frozen importlib._bootstrap_external>", line 1160, in get_code
  File "<frozen importlib._bootstrap_external>", line 1090, in source_to_code
  File "<frozen importlib._bootstrap>", line 488, in _call_with_frames_removed
  File "/home/malhar/User_Drive/Projects/cn_ddos_protection_python/webserver/main.py", line 3
    from mysql
              ^
SyntaxError: invalid syntax
[2024-12-28 02:17:01 +0530] [25063] [INFO] Booting worker with pid: 25063
[2024-12-28 02:17:01 +0530] [25063] [ERROR] invalid syntax (main.py, line 3)
Traceback (most recent call last):
  File "/home/malhar/User_Drive/Projects/cn_ddos_protection_python/webserver/webs_venv/lib/python3.13/site-packages/gunicorn/workers/base.py", line 147, in load_wsgi
    self.wsgi = self.app.wsgi()
                ~~~~~~~~~~~~~^^
  File "/home/malhar/User_Drive/Projects/cn_ddos_protection_python/webserver/webs_venv/lib/python3.13/site-packages/gunicorn/app/base.py", line 66, in wsgi
    self.callable = self.load()
                    ~~~~~~~~~^^
  File "/home/malhar/User_Drive/Projects/cn_ddos_protection_python/webserver/webs_venv/lib/python3.13/site-packages/gunicorn/app/wsgiapp.py", line 57, in load
    return self.load_wsgiapp()
           ~~~~~~~~~~~~~~~~~^^
  File "/home/malhar/User_Drive/Projects/cn_ddos_protection_python/webserver/webs_venv/lib/python3.13/site-packages/gunicorn/app/wsgiapp.py", line 47, in load_wsgiapp
    return util.import_app(self.app_uri)
           ~~~~~~~~~~~~~~~^^^^^^^^^^^^^^
  File "/home/malhar/User_Drive/Projects/cn_ddos_protection_python/webserver/webs_venv/lib/python3.13/site-packages/gunicorn/util.py", line 370, in import_app
    mod = importlib.import_module(module)
  File "/usr/lib/python3.13/importlib/__init__.py", line 88, in import_module
    return _bootstrap._gcd_import(name[level:], package, level)
           ~~~~~~~~~~~~~~~~~~~~~~^^^^^^^^^^^^^^^^^^^^^^^^^^^^^^
  File "<frozen importlib._bootstrap>", line 1387, in _gcd_import
  File "<frozen importlib._bootstrap>", line 1360, in _find_and_load
  File "<frozen importlib._bootstrap>", line 1331, in _find_and_load_unlocked
  File "<frozen importlib._bootstrap>", line 935, in _load_unlocked
  File "<frozen importlib._bootstrap_external>", line 1022, in exec_module
  File "<frozen importlib._bootstrap_external>", line 1160, in get_code
  File "<frozen importlib._bootstrap_external>", line 1090, in source_to_code
  File "<frozen importlib._bootstrap>", line 488, in _call_with_frames_removed
  File "/home/malhar/User_Drive/Projects/cn_ddos_protection_python/webserver/main.py", line 3
    from mysql
              ^
SyntaxError: invalid syntax
[2024-12-28 02:17:07 +0530] [25053] [INFO] Worker reloading: /home/malhar/User_Drive/Projects/cn_ddos_protection_python/webserver/main.py modified
[2024-12-28 02:17:07 +0530] [25053] [INFO] Worker exiting (pid: 25053)
[2024-12-28 02:17:07 +0530] [25072] [INFO] Booting worker with pid: 25072
[2024-12-28 02:17:07 +0530] [25072] [ERROR] Expected one or more names after 'import' (main.py, line 3)
Traceback (most recent call last):
  File "/home/malhar/User_Drive/Projects/cn_ddos_protection_python/webserver/webs_venv/lib/python3.13/site-packages/gunicorn/workers/base.py", line 147, in load_wsgi
    self.wsgi = self.app.wsgi()
                ~~~~~~~~~~~~~^^
  File "/home/malhar/User_Drive/Projects/cn_ddos_protection_python/webserver/webs_venv/lib/python3.13/site-packages/gunicorn/app/base.py", line 66, in wsgi
    self.callable = self.load()
                    ~~~~~~~~~^^
  File "/home/malhar/User_Drive/Projects/cn_ddos_protection_python/webserver/webs_venv/lib/python3.13/site-packages/gunicorn/app/wsgiapp.py", line 57, in load
    return self.load_wsgiapp()
           ~~~~~~~~~~~~~~~~~^^
  File "/home/malhar/User_Drive/Projects/cn_ddos_protection_python/webserver/webs_venv/lib/python3.13/site-packages/gunicorn/app/wsgiapp.py", line 47, in load_wsgiapp
    return util.import_app(self.app_uri)
           ~~~~~~~~~~~~~~~^^^^^^^^^^^^^^
  File "/home/malhar/User_Drive/Projects/cn_ddos_protection_python/webserver/webs_venv/lib/python3.13/site-packages/gunicorn/util.py", line 370, in import_app
    mod = importlib.import_module(module)
  File "/usr/lib/python3.13/importlib/__init__.py", line 88, in import_module
    return _bootstrap._gcd_import(name[level:], package, level)
           ~~~~~~~~~~~~~~~~~~~~~~^^^^^^^^^^^^^^^^^^^^^^^^^^^^^^
  File "<frozen importlib._bootstrap>", line 1387, in _gcd_import
  File "<frozen importlib._bootstrap>", line 1360, in _find_and_load
  File "<frozen importlib._bootstrap>", line 1331, in _find_and_load_unlocked
  File "<frozen importlib._bootstrap>", line 935, in _load_unlocked
  File "<frozen importlib._bootstrap_external>", line 1022, in exec_module
  File "<frozen importlib._bootstrap_external>", line 1160, in get_code
  File "<frozen importlib._bootstrap_external>", line 1090, in source_to_code
  File "<frozen importlib._bootstrap>", line 488, in _call_with_frames_removed
  File "/home/malhar/User_Drive/Projects/cn_ddos_protection_python/webserver/main.py", line 3
    from mysql.connector import 
                                ^
SyntaxError: Expected one or more names after 'import'
[2024-12-28 02:17:07 +0530] [25055] [INFO] Worker reloading: /home/malhar/User_Drive/Projects/cn_ddos_protection_python/webserver/main.py modified
[2024-12-28 02:17:07 +0530] [25055] [INFO] Worker exiting (pid: 25055)
[2024-12-28 02:17:07 +0530] [25074] [INFO] Booting worker with pid: 25074
[2024-12-28 02:17:07 +0530] [25074] [ERROR] Expected one or more names after 'import' (main.py, line 3)
Traceback (most recent call last):
  File "/home/malhar/User_Drive/Projects/cn_ddos_protection_python/webserver/webs_venv/lib/python3.13/site-packages/gunicorn/workers/base.py", line 147, in load_wsgi
    self.wsgi = self.app.wsgi()
                ~~~~~~~~~~~~~^^
  File "/home/malhar/User_Drive/Projects/cn_ddos_protection_python/webserver/webs_venv/lib/python3.13/site-packages/gunicorn/app/base.py", line 66, in wsgi
    self.callable = self.load()
                    ~~~~~~~~~^^
  File "/home/malhar/User_Drive/Projects/cn_ddos_protection_python/webserver/webs_venv/lib/python3.13/site-packages/gunicorn/app/wsgiapp.py", line 57, in load
    return self.load_wsgiapp()
           ~~~~~~~~~~~~~~~~~^^
  File "/home/malhar/User_Drive/Projects/cn_ddos_protection_python/webserver/webs_venv/lib/python3.13/site-packages/gunicorn/app/wsgiapp.py", line 47, in load_wsgiapp
    return util.import_app(self.app_uri)
           ~~~~~~~~~~~~~~~^^^^^^^^^^^^^^
  File "/home/malhar/User_Drive/Projects/cn_ddos_protection_python/webserver/webs_venv/lib/python3.13/site-packages/gunicorn/util.py", line 370, in import_app
    mod = importlib.import_module(module)
  File "/usr/lib/python3.13/importlib/__init__.py", line 88, in import_module
    return _bootstrap._gcd_import(name[level:], package, level)
           ~~~~~~~~~~~~~~~~~~~~~~^^^^^^^^^^^^^^^^^^^^^^^^^^^^^^
  File "<frozen importlib._bootstrap>", line 1387, in _gcd_import
  File "<frozen importlib._bootstrap>", line 1360, in _find_and_load
  File "<frozen importlib._bootstrap>", line 1331, in _find_and_load_unlocked
  File "<frozen importlib._bootstrap>", line 935, in _load_unlocked
  File "<frozen importlib._bootstrap_external>", line 1022, in exec_module
  File "<frozen importlib._bootstrap_external>", line 1160, in get_code
  File "<frozen importlib._bootstrap_external>", line 1090, in source_to_code
  File "<frozen importlib._bootstrap>", line 488, in _call_with_frames_removed
  File "/home/malhar/User_Drive/Projects/cn_ddos_protection_python/webserver/main.py", line 3
    from mysql.connector import 
                                ^
SyntaxError: Expected one or more names after 'import'
[2024-12-28 02:17:07 +0530] [25057] [INFO] Worker reloading: /home/malhar/User_Drive/Projects/cn_ddos_protection_python/webserver/main.py modified
[2024-12-28 02:17:07 +0530] [25057] [INFO] Worker exiting (pid: 25057)
[2024-12-28 02:17:07 +0530] [25059] [INFO] Worker reloading: /home/malhar/User_Drive/Projects/cn_ddos_protection_python/webserver/main.py modified
[2024-12-28 02:17:07 +0530] [25059] [INFO] Worker exiting (pid: 25059)
[2024-12-28 02:17:07 +0530] [25076] [INFO] Booting worker with pid: 25076
[2024-12-28 02:17:07 +0530] [25076] [ERROR] Expected one or more names after 'import' (main.py, line 3)
Traceback (most recent call last):
  File "/home/malhar/User_Drive/Projects/cn_ddos_protection_python/webserver/webs_venv/lib/python3.13/site-packages/gunicorn/workers/base.py", line 147, in load_wsgi
    self.wsgi = self.app.wsgi()
                ~~~~~~~~~~~~~^^
  File "/home/malhar/User_Drive/Projects/cn_ddos_protection_python/webserver/webs_venv/lib/python3.13/site-packages/gunicorn/app/base.py", line 66, in wsgi
    self.callable = self.load()
                    ~~~~~~~~~^^
  File "/home/malhar/User_Drive/Projects/cn_ddos_protection_python/webserver/webs_venv/lib/python3.13/site-packages/gunicorn/app/wsgiapp.py", line 57, in load
    return self.load_wsgiapp()
           ~~~~~~~~~~~~~~~~~^^
  File "/home/malhar/User_Drive/Projects/cn_ddos_protection_python/webserver/webs_venv/lib/python3.13/site-packages/gunicorn/app/wsgiapp.py", line 47, in load_wsgiapp
    return util.import_app(self.app_uri)
           ~~~~~~~~~~~~~~~^^^^^^^^^^^^^^
  File "/home/malhar/User_Drive/Projects/cn_ddos_protection_python/webserver/webs_venv/lib/python3.13/site-packages/gunicorn/util.py", line 370, in import_app
    mod = importlib.import_module(module)
  File "/usr/lib/python3.13/importlib/__init__.py", line 88, in import_module
    return _bootstrap._gcd_import(name[level:], package, level)
           ~~~~~~~~~~~~~~~~~~~~~~^^^^^^^^^^^^^^^^^^^^^^^^^^^^^^
  File "<frozen importlib._bootstrap>", line 1387, in _gcd_import
  File "<frozen importlib._bootstrap>", line 1360, in _find_and_load
  File "<frozen importlib._bootstrap>", line 1331, in _find_and_load_unlocked
  File "<frozen importlib._bootstrap>", line 935, in _load_unlocked
  File "<frozen importlib._bootstrap_external>", line 1022, in exec_module
  File "<frozen importlib._bootstrap_external>", line 1160, in get_code
  File "<frozen importlib._bootstrap_external>", line 1090, in source_to_code
  File "<frozen importlib._bootstrap>", line 488, in _call_with_frames_removed
  File "/home/malhar/User_Drive/Projects/cn_ddos_protection_python/webserver/main.py", line 3
    from mysql.connector import 
                                ^
SyntaxError: Expected one or more names after 'import'
[2024-12-28 02:17:07 +0530] [25078] [INFO] Booting worker with pid: 25078
[2024-12-28 02:17:07 +0530] [25078] [ERROR] Expected one or more names after 'import' (main.py, line 3)
Traceback (most recent call last):
  File "/home/malhar/User_Drive/Projects/cn_ddos_protection_python/webserver/webs_venv/lib/python3.13/site-packages/gunicorn/workers/base.py", line 147, in load_wsgi
    self.wsgi = self.app.wsgi()
                ~~~~~~~~~~~~~^^
  File "/home/malhar/User_Drive/Projects/cn_ddos_protection_python/webserver/webs_venv/lib/python3.13/site-packages/gunicorn/app/base.py", line 66, in wsgi
    self.callable = self.load()
                    ~~~~~~~~~^^
  File "/home/malhar/User_Drive/Projects/cn_ddos_protection_python/webserver/webs_venv/lib/python3.13/site-packages/gunicorn/app/wsgiapp.py", line 57, in load
    return self.load_wsgiapp()
           ~~~~~~~~~~~~~~~~~^^
  File "/home/malhar/User_Drive/Projects/cn_ddos_protection_python/webserver/webs_venv/lib/python3.13/site-packages/gunicorn/app/wsgiapp.py", line 47, in load_wsgiapp
    return util.import_app(self.app_uri)
           ~~~~~~~~~~~~~~~^^^^^^^^^^^^^^
  File "/home/malhar/User_Drive/Projects/cn_ddos_protection_python/webserver/webs_venv/lib/python3.13/site-packages/gunicorn/util.py", line 370, in import_app
    mod = importlib.import_module(module)
  File "/usr/lib/python3.13/importlib/__init__.py", line 88, in import_module
    return _bootstrap._gcd_import(name[level:], package, level)
           ~~~~~~~~~~~~~~~~~~~~~~^^^^^^^^^^^^^^^^^^^^^^^^^^^^^^
  File "<frozen importlib._bootstrap>", line 1387, in _gcd_import
  File "<frozen importlib._bootstrap>", line 1360, in _find_and_load
  File "<frozen importlib._bootstrap>", line 1331, in _find_and_load_unlocked
  File "<frozen importlib._bootstrap>", line 935, in _load_unlocked
  File "<frozen importlib._bootstrap_external>", line 1022, in exec_module
  File "<frozen importlib._bootstrap_external>", line 1160, in get_code
  File "<frozen importlib._bootstrap_external>", line 1090, in source_to_code
  File "<frozen importlib._bootstrap>", line 488, in _call_with_frames_removed
  File "/home/malhar/User_Drive/Projects/cn_ddos_protection_python/webserver/main.py", line 3
    from mysql.connector import 
                                ^
SyntaxError: Expected one or more names after 'import'
[2024-12-28 02:17:07 +0530] [25061] [INFO] Worker reloading: /home/malhar/User_Drive/Projects/cn_ddos_protection_python/webserver/main.py modified
[2024-12-28 02:17:07 +0530] [25061] [INFO] Worker exiting (pid: 25061)
[2024-12-28 02:17:07 +0530] [25080] [INFO] Booting worker with pid: 25080
[2024-12-28 02:17:07 +0530] [25080] [ERROR] Expected one or more names after 'import' (main.py, line 3)
Traceback (most recent call last):
  File "/home/malhar/User_Drive/Projects/cn_ddos_protection_python/webserver/webs_venv/lib/python3.13/site-packages/gunicorn/workers/base.py", line 147, in load_wsgi
    self.wsgi = self.app.wsgi()
                ~~~~~~~~~~~~~^^
  File "/home/malhar/User_Drive/Projects/cn_ddos_protection_python/webserver/webs_venv/lib/python3.13/site-packages/gunicorn/app/base.py", line 66, in wsgi
    self.callable = self.load()
                    ~~~~~~~~~^^
  File "/home/malhar/User_Drive/Projects/cn_ddos_protection_python/webserver/webs_venv/lib/python3.13/site-packages/gunicorn/app/wsgiapp.py", line 57, in load
    return self.load_wsgiapp()
           ~~~~~~~~~~~~~~~~~^^
  File "/home/malhar/User_Drive/Projects/cn_ddos_protection_python/webserver/webs_venv/lib/python3.13/site-packages/gunicorn/app/wsgiapp.py", line 47, in load_wsgiapp
    return util.import_app(self.app_uri)
           ~~~~~~~~~~~~~~~^^^^^^^^^^^^^^
  File "/home/malhar/User_Drive/Projects/cn_ddos_protection_python/webserver/webs_venv/lib/python3.13/site-packages/gunicorn/util.py", line 370, in import_app
    mod = importlib.import_module(module)
  File "/usr/lib/python3.13/importlib/__init__.py", line 88, in import_module
    return _bootstrap._gcd_import(name[level:], package, level)
           ~~~~~~~~~~~~~~~~~~~~~~^^^^^^^^^^^^^^^^^^^^^^^^^^^^^^
  File "<frozen importlib._bootstrap>", line 1387, in _gcd_import
  File "<frozen importlib._bootstrap>", line 1360, in _find_and_load
  File "<frozen importlib._bootstrap>", line 1331, in _find_and_load_unlocked
  File "<frozen importlib._bootstrap>", line 935, in _load_unlocked
  File "<frozen importlib._bootstrap_external>", line 1022, in exec_module
  File "<frozen importlib._bootstrap_external>", line 1160, in get_code
  File "<frozen importlib._bootstrap_external>", line 1090, in source_to_code
  File "<frozen importlib._bootstrap>", line 488, in _call_with_frames_removed
  File "/home/malhar/User_Drive/Projects/cn_ddos_protection_python/webserver/main.py", line 3
    from mysql.connector import 
                                ^
SyntaxError: Expected one or more names after 'import'
[2024-12-28 02:17:07 +0530] [25063] [INFO] Worker reloading: /home/malhar/User_Drive/Projects/cn_ddos_protection_python/webserver/main.py modified
[2024-12-28 02:17:07 +0530] [25063] [INFO] Worker exiting (pid: 25063)
[2024-12-28 02:17:07 +0530] [25082] [INFO] Booting worker with pid: 25082
[2024-12-28 02:17:07 +0530] [25082] [ERROR] Expected one or more names after 'import' (main.py, line 3)
Traceback (most recent call last):
  File "/home/malhar/User_Drive/Projects/cn_ddos_protection_python/webserver/webs_venv/lib/python3.13/site-packages/gunicorn/workers/base.py", line 147, in load_wsgi
    self.wsgi = self.app.wsgi()
                ~~~~~~~~~~~~~^^
  File "/home/malhar/User_Drive/Projects/cn_ddos_protection_python/webserver/webs_venv/lib/python3.13/site-packages/gunicorn/app/base.py", line 66, in wsgi
    self.callable = self.load()
                    ~~~~~~~~~^^
  File "/home/malhar/User_Drive/Projects/cn_ddos_protection_python/webserver/webs_venv/lib/python3.13/site-packages/gunicorn/app/wsgiapp.py", line 57, in load
    return self.load_wsgiapp()
           ~~~~~~~~~~~~~~~~~^^
  File "/home/malhar/User_Drive/Projects/cn_ddos_protection_python/webserver/webs_venv/lib/python3.13/site-packages/gunicorn/app/wsgiapp.py", line 47, in load_wsgiapp
    return util.import_app(self.app_uri)
           ~~~~~~~~~~~~~~~^^^^^^^^^^^^^^
  File "/home/malhar/User_Drive/Projects/cn_ddos_protection_python/webserver/webs_venv/lib/python3.13/site-packages/gunicorn/util.py", line 370, in import_app
    mod = importlib.import_module(module)
  File "/usr/lib/python3.13/importlib/__init__.py", line 88, in import_module
    return _bootstrap._gcd_import(name[level:], package, level)
           ~~~~~~~~~~~~~~~~~~~~~~^^^^^^^^^^^^^^^^^^^^^^^^^^^^^^
  File "<frozen importlib._bootstrap>", line 1387, in _gcd_import
  File "<frozen importlib._bootstrap>", line 1360, in _find_and_load
  File "<frozen importlib._bootstrap>", line 1331, in _find_and_load_unlocked
  File "<frozen importlib._bootstrap>", line 935, in _load_unlocked
  File "<frozen importlib._bootstrap_external>", line 1022, in exec_module
  File "<frozen importlib._bootstrap_external>", line 1160, in get_code
  File "<frozen importlib._bootstrap_external>", line 1090, in source_to_code
  File "<frozen importlib._bootstrap>", line 488, in _call_with_frames_removed
  File "/home/malhar/User_Drive/Projects/cn_ddos_protection_python/webserver/main.py", line 3
    from mysql.connector import 
                                ^
SyntaxError: Expected one or more names after 'import'
[2024-12-28 02:17:08 +0530] [25045] [INFO] Worker reloading: /home/malhar/User_Drive/Projects/cn_ddos_protection_python/webserver/main.py modified
[2024-12-28 02:17:08 +0530] [25045] [INFO] Worker exiting (pid: 25045)
[2024-12-28 02:17:08 +0530] [25090] [INFO] Booting worker with pid: 25090
[2024-12-28 02:17:08 +0530] [25090] [ERROR] Expected one or more names after 'import' (main.py, line 3)
Traceback (most recent call last):
  File "/home/malhar/User_Drive/Projects/cn_ddos_protection_python/webserver/webs_venv/lib/python3.13/site-packages/gunicorn/workers/base.py", line 147, in load_wsgi
    self.wsgi = self.app.wsgi()
                ~~~~~~~~~~~~~^^
  File "/home/malhar/User_Drive/Projects/cn_ddos_protection_python/webserver/webs_venv/lib/python3.13/site-packages/gunicorn/app/base.py", line 66, in wsgi
    self.callable = self.load()
                    ~~~~~~~~~^^
  File "/home/malhar/User_Drive/Projects/cn_ddos_protection_python/webserver/webs_venv/lib/python3.13/site-packages/gunicorn/app/wsgiapp.py", line 57, in load
    return self.load_wsgiapp()
           ~~~~~~~~~~~~~~~~~^^
  File "/home/malhar/User_Drive/Projects/cn_ddos_protection_python/webserver/webs_venv/lib/python3.13/site-packages/gunicorn/app/wsgiapp.py", line 47, in load_wsgiapp
    return util.import_app(self.app_uri)
           ~~~~~~~~~~~~~~~^^^^^^^^^^^^^^
  File "/home/malhar/User_Drive/Projects/cn_ddos_protection_python/webserver/webs_venv/lib/python3.13/site-packages/gunicorn/util.py", line 370, in import_app
    mod = importlib.import_module(module)
  File "/usr/lib/python3.13/importlib/__init__.py", line 88, in import_module
    return _bootstrap._gcd_import(name[level:], package, level)
           ~~~~~~~~~~~~~~~~~~~~~~^^^^^^^^^^^^^^^^^^^^^^^^^^^^^^
  File "<frozen importlib._bootstrap>", line 1387, in _gcd_import
  File "<frozen importlib._bootstrap>", line 1360, in _find_and_load
  File "<frozen importlib._bootstrap>", line 1331, in _find_and_load_unlocked
  File "<frozen importlib._bootstrap>", line 935, in _load_unlocked
  File "<frozen importlib._bootstrap_external>", line 1022, in exec_module
  File "<frozen importlib._bootstrap_external>", line 1160, in get_code
  File "<frozen importlib._bootstrap_external>", line 1090, in source_to_code
  File "<frozen importlib._bootstrap>", line 488, in _call_with_frames_removed
  File "/home/malhar/User_Drive/Projects/cn_ddos_protection_python/webserver/main.py", line 3
    from mysql.connector import 
                                ^
SyntaxError: Expected one or more names after 'import'
[2024-12-28 02:17:08 +0530] [25047] [INFO] Worker reloading: /home/malhar/User_Drive/Projects/cn_ddos_protection_python/webserver/main.py modified
[2024-12-28 02:17:08 +0530] [25047] [INFO] Worker exiting (pid: 25047)
[2024-12-28 02:17:08 +0530] [25092] [INFO] Booting worker with pid: 25092
[2024-12-28 02:17:08 +0530] [25092] [ERROR] Expected one or more names after 'import' (main.py, line 3)
Traceback (most recent call last):
  File "/home/malhar/User_Drive/Projects/cn_ddos_protection_python/webserver/webs_venv/lib/python3.13/site-packages/gunicorn/workers/base.py", line 147, in load_wsgi
    self.wsgi = self.app.wsgi()
                ~~~~~~~~~~~~~^^
  File "/home/malhar/User_Drive/Projects/cn_ddos_protection_python/webserver/webs_venv/lib/python3.13/site-packages/gunicorn/app/base.py", line 66, in wsgi
    self.callable = self.load()
                    ~~~~~~~~~^^
  File "/home/malhar/User_Drive/Projects/cn_ddos_protection_python/webserver/webs_venv/lib/python3.13/site-packages/gunicorn/app/wsgiapp.py", line 57, in load
    return self.load_wsgiapp()
           ~~~~~~~~~~~~~~~~~^^
  File "/home/malhar/User_Drive/Projects/cn_ddos_protection_python/webserver/webs_venv/lib/python3.13/site-packages/gunicorn/app/wsgiapp.py", line 47, in load_wsgiapp
    return util.import_app(self.app_uri)
           ~~~~~~~~~~~~~~~^^^^^^^^^^^^^^
  File "/home/malhar/User_Drive/Projects/cn_ddos_protection_python/webserver/webs_venv/lib/python3.13/site-packages/gunicorn/util.py", line 370, in import_app
    mod = importlib.import_module(module)
  File "/usr/lib/python3.13/importlib/__init__.py", line 88, in import_module
    return _bootstrap._gcd_import(name[level:], package, level)
           ~~~~~~~~~~~~~~~~~~~~~~^^^^^^^^^^^^^^^^^^^^^^^^^^^^^^
  File "<frozen importlib._bootstrap>", line 1387, in _gcd_import
  File "<frozen importlib._bootstrap>", line 1360, in _find_and_load
  File "<frozen importlib._bootstrap>", line 1331, in _find_and_load_unlocked
  File "<frozen importlib._bootstrap>", line 935, in _load_unlocked
  File "<frozen importlib._bootstrap_external>", line 1022, in exec_module
  File "<frozen importlib._bootstrap_external>", line 1160, in get_code
  File "<frozen importlib._bootstrap_external>", line 1090, in source_to_code
  File "<frozen importlib._bootstrap>", line 488, in _call_with_frames_removed
  File "/home/malhar/User_Drive/Projects/cn_ddos_protection_python/webserver/main.py", line 3
    from mysql.connector import 
                                ^
SyntaxError: Expected one or more names after 'import'
[2024-12-28 02:17:08 +0530] [25049] [INFO] Worker reloading: /home/malhar/User_Drive/Projects/cn_ddos_protection_python/webserver/main.py modified
[2024-12-28 02:17:08 +0530] [25049] [INFO] Worker exiting (pid: 25049)
[2024-12-28 02:17:08 +0530] [25051] [INFO] Worker reloading: /home/malhar/User_Drive/Projects/cn_ddos_protection_python/webserver/main.py modified
[2024-12-28 02:17:08 +0530] [25051] [INFO] Worker exiting (pid: 25051)
[2024-12-28 02:17:08 +0530] [25094] [INFO] Booting worker with pid: 25094
[2024-12-28 02:17:08 +0530] [25094] [ERROR] Expected one or more names after 'import' (main.py, line 3)
Traceback (most recent call last):
  File "/home/malhar/User_Drive/Projects/cn_ddos_protection_python/webserver/webs_venv/lib/python3.13/site-packages/gunicorn/workers/base.py", line 147, in load_wsgi
    self.wsgi = self.app.wsgi()
                ~~~~~~~~~~~~~^^
  File "/home/malhar/User_Drive/Projects/cn_ddos_protection_python/webserver/webs_venv/lib/python3.13/site-packages/gunicorn/app/base.py", line 66, in wsgi
    self.callable = self.load()
                    ~~~~~~~~~^^
  File "/home/malhar/User_Drive/Projects/cn_ddos_protection_python/webserver/webs_venv/lib/python3.13/site-packages/gunicorn/app/wsgiapp.py", line 57, in load
    return self.load_wsgiapp()
           ~~~~~~~~~~~~~~~~~^^
  File "/home/malhar/User_Drive/Projects/cn_ddos_protection_python/webserver/webs_venv/lib/python3.13/site-packages/gunicorn/app/wsgiapp.py", line 47, in load_wsgiapp
    return util.import_app(self.app_uri)
           ~~~~~~~~~~~~~~~^^^^^^^^^^^^^^
  File "/home/malhar/User_Drive/Projects/cn_ddos_protection_python/webserver/webs_venv/lib/python3.13/site-packages/gunicorn/util.py", line 370, in import_app
    mod = importlib.import_module(module)
  File "/usr/lib/python3.13/importlib/__init__.py", line 88, in import_module
    return _bootstrap._gcd_import(name[level:], package, level)
           ~~~~~~~~~~~~~~~~~~~~~~^^^^^^^^^^^^^^^^^^^^^^^^^^^^^^
  File "<frozen importlib._bootstrap>", line 1387, in _gcd_import
  File "<frozen importlib._bootstrap>", line 1360, in _find_and_load
  File "<frozen importlib._bootstrap>", line 1331, in _find_and_load_unlocked
  File "<frozen importlib._bootstrap>", line 935, in _load_unlocked
  File "<frozen importlib._bootstrap_external>", line 1022, in exec_module
  File "<frozen importlib._bootstrap_external>", line 1160, in get_code
  File "<frozen importlib._bootstrap_external>", line 1090, in source_to_code
  File "<frozen importlib._bootstrap>", line 488, in _call_with_frames_removed
  File "/home/malhar/User_Drive/Projects/cn_ddos_protection_python/webserver/main.py", line 3
    from mysql.connector import 
                                ^
SyntaxError: Expected one or more names after 'import'
[2024-12-28 02:17:08 +0530] [25096] [INFO] Booting worker with pid: 25096
[2024-12-28 02:17:08 +0530] [25096] [ERROR] Expected one or more names after 'import' (main.py, line 3)
Traceback (most recent call last):
  File "/home/malhar/User_Drive/Projects/cn_ddos_protection_python/webserver/webs_venv/lib/python3.13/site-packages/gunicorn/workers/base.py", line 147, in load_wsgi
    self.wsgi = self.app.wsgi()
                ~~~~~~~~~~~~~^^
  File "/home/malhar/User_Drive/Projects/cn_ddos_protection_python/webserver/webs_venv/lib/python3.13/site-packages/gunicorn/app/base.py", line 66, in wsgi
    self.callable = self.load()
                    ~~~~~~~~~^^
  File "/home/malhar/User_Drive/Projects/cn_ddos_protection_python/webserver/webs_venv/lib/python3.13/site-packages/gunicorn/app/wsgiapp.py", line 57, in load
    return self.load_wsgiapp()
           ~~~~~~~~~~~~~~~~~^^
  File "/home/malhar/User_Drive/Projects/cn_ddos_protection_python/webserver/webs_venv/lib/python3.13/site-packages/gunicorn/app/wsgiapp.py", line 47, in load_wsgiapp
    return util.import_app(self.app_uri)
           ~~~~~~~~~~~~~~~^^^^^^^^^^^^^^
  File "/home/malhar/User_Drive/Projects/cn_ddos_protection_python/webserver/webs_venv/lib/python3.13/site-packages/gunicorn/util.py", line 370, in import_app
    mod = importlib.import_module(module)
  File "/usr/lib/python3.13/importlib/__init__.py", line 88, in import_module
    return _bootstrap._gcd_import(name[level:], package, level)
           ~~~~~~~~~~~~~~~~~~~~~~^^^^^^^^^^^^^^^^^^^^^^^^^^^^^^
  File "<frozen importlib._bootstrap>", line 1387, in _gcd_import
  File "<frozen importlib._bootstrap>", line 1360, in _find_and_load
  File "<frozen importlib._bootstrap>", line 1331, in _find_and_load_unlocked
  File "<frozen importlib._bootstrap>", line 935, in _load_unlocked
  File "<frozen importlib._bootstrap_external>", line 1022, in exec_module
  File "<frozen importlib._bootstrap_external>", line 1160, in get_code
  File "<frozen importlib._bootstrap_external>", line 1090, in source_to_code
  File "<frozen importlib._bootstrap>", line 488, in _call_with_frames_removed
  File "/home/malhar/User_Drive/Projects/cn_ddos_protection_python/webserver/main.py", line 3
    from mysql.connector import 
                                ^
SyntaxError: Expected one or more names after 'import'
[2024-12-28 02:17:10 +0530] [25074] [INFO] Worker reloading: /home/malhar/User_Drive/Projects/cn_ddos_protection_python/webserver/main.py modified
[2024-12-28 02:17:10 +0530] [25074] [INFO] Worker exiting (pid: 25074)
[2024-12-28 02:17:10 +0530] [25102] [INFO] Booting worker with pid: 25102
[2024-12-28 02:17:10 +0530] [25076] [INFO] Worker reloading: /home/malhar/User_Drive/Projects/cn_ddos_protection_python/webserver/main.py modified
[2024-12-28 02:17:10 +0530] [25076] [INFO] Worker exiting (pid: 25076)
[2024-12-28 02:17:10 +0530] [25103] [INFO] Booting worker with pid: 25103
[2024-12-28 02:17:10 +0530] [25078] [INFO] Worker reloading: /home/malhar/User_Drive/Projects/cn_ddos_protection_python/webserver/main.py modified
[2024-12-28 02:17:10 +0530] [25078] [INFO] Worker exiting (pid: 25078)
[2024-12-28 02:17:10 +0530] [25080] [INFO] Worker reloading: /home/malhar/User_Drive/Projects/cn_ddos_protection_python/webserver/main.py modified
[2024-12-28 02:17:10 +0530] [25080] [INFO] Worker exiting (pid: 25080)
[2024-12-28 02:17:10 +0530] [25105] [INFO] Booting worker with pid: 25105
[2024-12-28 02:17:10 +0530] [25082] [INFO] Worker reloading: /home/malhar/User_Drive/Projects/cn_ddos_protection_python/webserver/main.py modified
[2024-12-28 02:17:10 +0530] [25082] [INFO] Worker exiting (pid: 25082)
[2024-12-28 02:17:10 +0530] [25107] [INFO] Booting worker with pid: 25107
[2024-12-28 02:17:10 +0530] [25109] [INFO] Booting worker with pid: 25109
[2024-12-28 02:17:11 +0530] [25090] [INFO] Worker reloading: /home/malhar/User_Drive/Projects/cn_ddos_protection_python/webserver/main.py modified
[2024-12-28 02:17:11 +0530] [25090] [INFO] Worker exiting (pid: 25090)
[2024-12-28 02:17:11 +0530] [25113] [INFO] Booting worker with pid: 25113
[2024-12-28 02:17:11 +0530] [25092] [INFO] Worker reloading: /home/malhar/User_Drive/Projects/cn_ddos_protection_python/webserver/main.py modified
[2024-12-28 02:17:11 +0530] [25092] [INFO] Worker exiting (pid: 25092)
[2024-12-28 02:17:11 +0530] [25114] [INFO] Booting worker with pid: 25114
[2024-12-28 02:17:11 +0530] [25094] [INFO] Worker reloading: /home/malhar/User_Drive/Projects/cn_ddos_protection_python/webserver/main.py modified
[2024-12-28 02:17:11 +0530] [25094] [INFO] Worker exiting (pid: 25094)
[2024-12-28 02:17:11 +0530] [25117] [INFO] Booting worker with pid: 25117
[2024-12-28 02:17:11 +0530] [25096] [INFO] Worker reloading: /home/malhar/User_Drive/Projects/cn_ddos_protection_python/webserver/main.py modified
[2024-12-28 02:17:11 +0530] [25096] [INFO] Worker exiting (pid: 25096)
[2024-12-28 02:17:11 +0530] [25072] [INFO] Worker reloading: /home/malhar/User_Drive/Projects/cn_ddos_protection_python/webserver/main.py modified
[2024-12-28 02:17:11 +0530] [25072] [INFO] Worker exiting (pid: 25072)
[2024-12-28 02:17:11 +0530] [25118] [INFO] Booting worker with pid: 25118
[2024-12-28 02:17:11 +0530] [25119] [INFO] Booting worker with pid: 25119
[2024-12-28 02:17:13 +0530] [25119] [INFO] Worker reloading: /home/malhar/User_Drive/Projects/cn_ddos_protection_python/webserver/main.py modified
[2024-12-28 02:17:13 +0530] [25119] [INFO] Worker exiting (pid: 25119)
[2024-12-28 02:17:13 +0530] [25124] [INFO] Booting worker with pid: 25124
[2024-12-28 02:17:13 +0530] [25102] [INFO] Worker reloading: /home/malhar/User_Drive/Projects/cn_ddos_protection_python/webserver/main.py modified
[2024-12-28 02:17:13 +0530] [25102] [INFO] Worker exiting (pid: 25102)
[2024-12-28 02:17:13 +0530] [25125] [INFO] Booting worker with pid: 25125
[2024-12-28 02:17:13 +0530] [25103] [INFO] Worker reloading: /home/malhar/User_Drive/Projects/cn_ddos_protection_python/webserver/main.py modified
[2024-12-28 02:17:13 +0530] [25103] [INFO] Worker exiting (pid: 25103)
[2024-12-28 02:17:13 +0530] [25126] [INFO] Booting worker with pid: 25126
[2024-12-28 02:17:13 +0530] [25105] [INFO] Worker reloading: /home/malhar/User_Drive/Projects/cn_ddos_protection_python/webserver/main.py modified
[2024-12-28 02:17:13 +0530] [25105] [INFO] Worker exiting (pid: 25105)
[2024-12-28 02:17:13 +0530] [25107] [INFO] Worker reloading: /home/malhar/User_Drive/Projects/cn_ddos_protection_python/webserver/main.py modified
[2024-12-28 02:17:13 +0530] [25107] [INFO] Worker exiting (pid: 25107)
[2024-12-28 02:17:13 +0530] [25129] [INFO] Booting worker with pid: 25129
[2024-12-28 02:17:13 +0530] [25109] [INFO] Worker reloading: /home/malhar/User_Drive/Projects/cn_ddos_protection_python/webserver/main.py modified
[2024-12-28 02:17:13 +0530] [25109] [INFO] Worker exiting (pid: 25109)
[2024-12-28 02:17:13 +0530] [25131] [INFO] Booting worker with pid: 25131
[2024-12-28 02:17:13 +0530] [25133] [INFO] Booting worker with pid: 25133
[2024-12-28 02:17:14 +0530] [25113] [INFO] Worker reloading: /home/malhar/User_Drive/Projects/cn_ddos_protection_python/webserver/main.py modified
[2024-12-28 02:17:14 +0530] [25113] [INFO] Worker exiting (pid: 25113)
[2024-12-28 02:17:14 +0530] [25136] [INFO] Booting worker with pid: 25136
[2024-12-28 02:17:14 +0530] [25114] [INFO] Worker reloading: /home/malhar/User_Drive/Projects/cn_ddos_protection_python/webserver/main.py modified
[2024-12-28 02:17:14 +0530] [25114] [INFO] Worker exiting (pid: 25114)
[2024-12-28 02:17:14 +0530] [25137] [INFO] Booting worker with pid: 25137
[2024-12-28 02:17:14 +0530] [25117] [INFO] Worker reloading: /home/malhar/User_Drive/Projects/cn_ddos_protection_python/webserver/main.py modified
[2024-12-28 02:17:14 +0530] [25117] [INFO] Worker exiting (pid: 25117)
[2024-12-28 02:17:14 +0530] [25150] [INFO] Booting worker with pid: 25150
[2024-12-28 02:17:14 +0530] [25118] [INFO] Worker reloading: /home/malhar/User_Drive/Projects/cn_ddos_protection_python/webserver/main.py modified
[2024-12-28 02:17:14 +0530] [25118] [INFO] Worker exiting (pid: 25118)
[2024-12-28 02:17:14 +0530] [25151] [INFO] Booting worker with pid: 25151
[2024-12-28 02:17:18 +0530] [25129] [INFO] Worker reloading: /home/malhar/User_Drive/Projects/cn_ddos_protection_python/webserver/main.py modified
[2024-12-28 02:17:18 +0530] [25129] [INFO] Worker exiting (pid: 25129)
[2024-12-28 02:17:19 +0530] [25131] [INFO] Worker reloading: /home/malhar/User_Drive/Projects/cn_ddos_protection_python/webserver/main.py modified
[2024-12-28 02:17:19 +0530] [25131] [INFO] Worker exiting (pid: 25131)
[2024-12-28 02:17:19 +0530] [25179] [INFO] Booting worker with pid: 25179
[2024-12-28 02:17:19 +0530] [25180] [INFO] Booting worker with pid: 25180
[2024-12-28 02:17:19 +0530] [25133] [INFO] Worker reloading: /home/malhar/User_Drive/Projects/cn_ddos_protection_python/webserver/main.py modified
[2024-12-28 02:17:19 +0530] [25133] [INFO] Worker exiting (pid: 25133)
[2024-12-28 02:17:19 +0530] [25181] [INFO] Booting worker with pid: 25181
[2024-12-28 02:17:19 +0530] [25136] [INFO] Worker reloading: /home/malhar/User_Drive/Projects/cn_ddos_protection_python/webserver/main.py modified
[2024-12-28 02:17:19 +0530] [25136] [INFO] Worker exiting (pid: 25136)
[2024-12-28 02:17:19 +0530] [25186] [INFO] Booting worker with pid: 25186
[2024-12-28 02:17:19 +0530] [25137] [INFO] Worker reloading: /home/malhar/User_Drive/Projects/cn_ddos_protection_python/webserver/main.py modified
[2024-12-28 02:17:19 +0530] [25137] [INFO] Worker exiting (pid: 25137)
[2024-12-28 02:17:19 +0530] [25187] [INFO] Booting worker with pid: 25187
[2024-12-28 02:17:19 +0530] [25150] [INFO] Worker reloading: /home/malhar/User_Drive/Projects/cn_ddos_protection_python/webserver/main.py modified
[2024-12-28 02:17:19 +0530] [25150] [INFO] Worker exiting (pid: 25150)
[2024-12-28 02:17:19 +0530] [25190] [INFO] Booting worker with pid: 25190
[2024-12-28 02:17:19 +0530] [25151] [INFO] Worker reloading: /home/malhar/User_Drive/Projects/cn_ddos_protection_python/webserver/main.py modified
[2024-12-28 02:17:19 +0530] [25151] [INFO] Worker exiting (pid: 25151)
[2024-12-28 02:17:19 +0530] [25124] [INFO] Worker reloading: /home/malhar/User_Drive/Projects/cn_ddos_protection_python/webserver/main.py modified
[2024-12-28 02:17:19 +0530] [25124] [INFO] Worker exiting (pid: 25124)
[2024-12-28 02:17:19 +0530] [25191] [INFO] Booting worker with pid: 25191
[2024-12-28 02:17:19 +0530] [25125] [INFO] Worker reloading: /home/malhar/User_Drive/Projects/cn_ddos_protection_python/webserver/main.py modified
[2024-12-28 02:17:19 +0530] [25125] [INFO] Worker exiting (pid: 25125)
[2024-12-28 02:17:19 +0530] [25192] [INFO] Booting worker with pid: 25192
[2024-12-28 02:17:19 +0530] [25126] [INFO] Worker reloading: /home/malhar/User_Drive/Projects/cn_ddos_protection_python/webserver/main.py modified
[2024-12-28 02:17:19 +0530] [25126] [INFO] Worker exiting (pid: 25126)
[2024-12-28 02:17:19 +0530] [25194] [INFO] Booting worker with pid: 25194
[2024-12-28 02:17:20 +0530] [25197] [INFO] Booting worker with pid: 25197
[2024-12-28 02:17:23 +0530] [25187] [INFO] Worker reloading: /home/malhar/User_Drive/Projects/cn_ddos_protection_python/webserver/main.py modified
[2024-12-28 02:17:23 +0530] [25187] [INFO] Worker exiting (pid: 25187)
[2024-12-28 02:17:23 +0530] [25204] [INFO] Booting worker with pid: 25204
[2024-12-28 02:17:23 +0530] [25204] [ERROR] Exception in worker process
Traceback (most recent call last):
  File "/home/malhar/User_Drive/Projects/cn_ddos_protection_python/webserver/webs_venv/lib/python3.13/site-packages/gunicorn/arbiter.py", line 608, in spawn_worker
    worker.init_process()
    ~~~~~~~~~~~~~~~~~~~^^
  File "/home/malhar/User_Drive/Projects/cn_ddos_protection_python/webserver/webs_venv/lib/python3.13/site-packages/gunicorn/workers/base.py", line 135, in init_process
    self.load_wsgi()
    ~~~~~~~~~~~~~~^^
  File "/home/malhar/User_Drive/Projects/cn_ddos_protection_python/webserver/webs_venv/lib/python3.13/site-packages/gunicorn/workers/base.py", line 147, in load_wsgi
    self.wsgi = self.app.wsgi()
                ~~~~~~~~~~~~~^^
  File "/home/malhar/User_Drive/Projects/cn_ddos_protection_python/webserver/webs_venv/lib/python3.13/site-packages/gunicorn/app/base.py", line 66, in wsgi
    self.callable = self.load()
                    ~~~~~~~~~^^
  File "/home/malhar/User_Drive/Projects/cn_ddos_protection_python/webserver/webs_venv/lib/python3.13/site-packages/gunicorn/app/wsgiapp.py", line 57, in load
    return self.load_wsgiapp()
           ~~~~~~~~~~~~~~~~~^^
  File "/home/malhar/User_Drive/Projects/cn_ddos_protection_python/webserver/webs_venv/lib/python3.13/site-packages/gunicorn/app/wsgiapp.py", line 47, in load_wsgiapp
    return util.import_app(self.app_uri)
           ~~~~~~~~~~~~~~~^^^^^^^^^^^^^^
  File "/home/malhar/User_Drive/Projects/cn_ddos_protection_python/webserver/webs_venv/lib/python3.13/site-packages/gunicorn/util.py", line 370, in import_app
    mod = importlib.import_module(module)
  File "/usr/lib/python3.13/importlib/__init__.py", line 88, in import_module
    return _bootstrap._gcd_import(name[level:], package, level)
           ~~~~~~~~~~~~~~~~~~~~~~^^^^^^^^^^^^^^^^^^^^^^^^^^^^^^
  File "<frozen importlib._bootstrap>", line 1387, in _gcd_import
  File "<frozen importlib._bootstrap>", line 1360, in _find_and_load
  File "<frozen importlib._bootstrap>", line 1331, in _find_and_load_unlocked
  File "<frozen importlib._bootstrap>", line 935, in _load_unlocked
  File "<frozen importlib._bootstrap_external>", line 1026, in exec_module
  File "<frozen importlib._bootstrap>", line 488, in _call_with_frames_removed
  File "/home/malhar/User_Drive/Projects/cn_ddos_protection_python/webserver/main.py", line 8, in <module>
    MY_SQL_HOST
NameError: name 'MY_SQL_HOST' is not defined
[2024-12-28 02:17:23 +0530] [25204] [INFO] Worker exiting (pid: 25204)
[2024-12-28 02:17:23 +0530] [11560] [ERROR] Worker (pid:25204) exited with code 3
[2024-12-28 02:17:23 +0530] [25197] [INFO] Worker exiting (pid: 25197)
[2024-12-28 02:17:23 +0530] [25180] [INFO] Worker exiting (pid: 25180)
[2024-12-28 02:17:23 +0530] [25194] [INFO] Worker exiting (pid: 25194)
[2024-12-28 02:17:23 +0530] [25191] [INFO] Worker exiting (pid: 25191)
[2024-12-28 02:17:23 +0530] [25186] [INFO] Worker exiting (pid: 25186)
[2024-12-28 02:17:23 +0530] [25192] [INFO] Worker exiting (pid: 25192)
[2024-12-28 02:17:23 +0530] [25179] [INFO] Worker exiting (pid: 25179)
[2024-12-28 02:17:23 +0530] [25181] [INFO] Worker exiting (pid: 25181)
[2024-12-28 02:17:23 +0530] [25190] [INFO] Worker exiting (pid: 25190)
[2024-12-28 02:17:24 +0530] [11560] [ERROR] Shutting down: Master
[2024-12-28 02:17:24 +0530] [11560] [ERROR] Reason: Worker failed to boot.
